Workbook
Name convert: #REF!
Name convert: #REF!
Name convert: '[1]Scratch Sheet'!$B$159:$D$166
Name convert: #REF!
Name convert: #REF!
Name convert: '[1]Scratch Sheet'!$B$159:$D$166
Name convert: #REF!
Name goldlook: #REF!
Name goldlook: #REF!
Name goldlook: '[1]Scratch Sheet'!$B$62:$C$68
Name goldlook: #REF!
Name goldlook: #REF!
Name goldlook: '[1]Scratch Sheet'!$B$62:$C$68
Name goldlook: #REF!
Name goldlook2: #REF!
Name goldlook2: #REF!
Name goldlook2: #REF!
Name goldlook2: #REF!
Name goldlook2: #REF!
Name goldlook2: #REF!
Name goldlook2: #REF!
Name grouplook: #REF!
Name grouplook: #REF!
Name grouplook: [2]Sheet1!$E$5:$F$52
Name grouplook: #REF!
Name grouplook: #REF!
Name grouplook: [2]Sheet1!$E$5:$F$52
Name grouplook: #REF!
Name platlook: #REF!
Name platlook: #REF!
Name platlook: '[1]Scratch Sheet'!$B$56:$E$59
Name platlook: #REF!
Name platlook: #REF!
Name platlook: '[1]Scratch Sheet'!$B$56:$E$59
Name platlook: #REF!
Name RRput: #REF!
Name RRput: #REF!
Name RRput: [3]Sheet3!$Q$226:$R$275
Name RRput: #REF!
Name RRput: #REF!
Name RRput: [3]Sheet3!$Q$226:$R$275
Name RRput: #REF!
Name RRput4: #REF!
Name RRput4: #REF!
Name RRput4: [4]Sheet3!$G$4:$I$53
Name RRput4: #REF!
Name RRput4: #REF!
Name RRput4: [4]Sheet3!$G$4:$I$53
Name RRput4: #REF!
Name translate: #REF!
Name translate: #REF!
Name translate: [5]advancement!$O$181:$P$236
Name translate: #REF!
Name translate: #REF!
Name translate: [6]advancement!$O$181:$P$236
Name translate: #REF!

Sheet CHICLETS MASTER S1
A1: 2026 NJO S1 | J1: 2026 NJO S1 | O1: 2026 NJO S1 | U1: 2026 NJO S1 | Z1: 2026 NJO S1 | AL1: 2026 NJO S1 | AU1: 2026 NJO S1
A2: SATURDAY, JULY 18 | J2: SATURDAY, JULY 18 | O2: SATURDAY, JULY 18 | U2: SATURDAY, JULY 18 | Z2: SATURDAY, JULY 18 | AL2: SATURDAY, JULY 18 | AU2: SATURDAY, JULY 18
B3: EL TORO HS 1 | C3: EL TORO HS 2 | D3: EL TORO HS 3 | E3: BECKMAN HS 2 | F3: SADDLEBACK COLLEGE 2 | G3: CAPISTRANO VALLEY HS 2 | H3: TUSTIN HS 2 | I3: OCEAN VIEW HS 2 | K3: GOLDEN WEST COLLEGE 2 | L3: LA HABRA HS | M3: PORTOLA HS 2 | N3: TRABUCO HILLS HS | P3: WOOLLETT FAR RIGHT | Q3: ALISO NIGUEL HS | R3: SAN CLEMENTE HS | S3: MISSION VIEJO HS | T3: LAGUNA HILLS HS | V3: UC IRVINE 1 | W3: BECKMAN HS 1 | X3: VILLA PARK HS | Y3: ORANGE HS | AA3: GARDEN GROVE HS | AB3: UC IRVINE 2 | AC3: SADDLEBACK COLLEGE 1 | AD3: BUENA PARK HS | AE3: OCEAN VIEW HS 1 | AF3: MARINA HS | AG3: GOLDEN WEST COLLEGE 1 | AH3: CAPISTRANO VALLEY HS 1 | AI3: PORTOLA HS 1 | AJ3: LA SERNA HS | AK3: LONG BEACH CC 2 | AM3: WOOLLETT NEAR RIGHT | AN3: LONG BEACH CC 1 | AO3: YORBA LINDA HS | AP3: FULLERTON HS | AQ3: EDISON HS | AR3: SONORA HS | AS3: SERVITE HS | AV3: SAN JUAN HILLS HS | AW3: EL MODENA HS | AX3: WOOLLETT NEAR LEFT | AY3: CHAPMAN UNIVERSITY | AZ3: WESTMINSTER HS | BA3: TUSTIN HS 1 | BB3: FULLERTON COLLEGE | BE3: =COUNTA(B3:BC3) -> 46
A4: 0.29166667 | C4: ='10U_Coed_Champ_36'!L36&"-"&'10U_Coed_Champ_36'!C36&"-"&TEXT('10U_Coed_Champ_36'!B16,"h:mm am/pm") -> 10C-002-Group H-7:00 AM | E4: ='10U_Coed_Champ_36'!L16&"-"&'10U_Coed_Champ_36'!C16&"-"&TEXT('10U_Coed_Champ_36'!B16,"h:mm am/pm") -> 10C-001-Group A-7:00 AM | F4: ='10U_Coed_Champ_36'!L56&"-"&'10U_Coed_Champ_36'!C56&"-"&TEXT('10U_Coed_Champ_36'!B36,"h:mm am/pm") -> 10C-003-Group I-7:00 AM | I4: ='10U_Coed_Classic 22 from 23'!L12&"-"&'10U_Coed_Classic 22 from 23'!C12&"-"&TEXT('10U_Coed_Classic 22 from 23'!B12,"h:mm am/pm") -> 10CX-001-Group-7:00 AM | J4: 0.29166667 | K4: ='12U_Coed_Champ-45'!L20&"-"&'12U_Coed_Champ-45'!C20&"-"&TEXT('12U_Coed_Champ-45'!B20,"h:mm am/pm") -> 12C-001-Group-7:00 AM | L4: ='12U_Coed_Champ-45'!L38&"-"&'12U_Coed_Champ-45'!C38&"-"&TEXT('12U_Coed_Champ-45'!B38,"h:mm am/pm") -> 12C-004-Group-7:00 AM | M4: ='12U_Coed_Champ-45'!L57&"-"&'12U_Coed_Champ-45'!C57&"-"&TEXT('12U_Coed_Champ-45'!B57,"h:mm am/pm") -> 12C-003-bracket-7:00 AM | N4: ='12U_Coed_Champ-45'!L75&"-"&'12U_Coed_Champ-45'!C75&"-"&TEXT('12U_Coed_Champ-45'!B75,"h:mm am/pm") -> 12C-002-bracket-7:00 AM | O4: 0.29166667 | P4: ='12U_F_Champ-52'!L29&"-"&'12U_F_Champ-52'!C29&"-"&TEXT('12U_F_Champ-52'!B29,"h:mm am/pm") -> 12G-005-Group-7:00 AM | Q4: ='12U_F_Champ-52'!L68&"-"&'12U_F_Champ-52'!C68&"-"&TEXT('12U_F_Champ-52'!B68,"h:mm am/pm") -> 12G-002-Group-7:00 AM | R4: ='12U_F_Champ-52'!L107&"-"&'12U_F_Champ-52'!C107&"-"&TEXT('12U_F_Champ-52'!B107,"h:mm am/pm") -> 12G-004-Group-7:00 AM | S4: ='12U_F_Champ-52'!L48&"-"&'12U_F_Champ-52'!C48&"-"&TEXT('12U_F_Champ-52'!B48,"h:mm am/pm") -> 12G-001-Group-7:00 AM | T4: ='12U_F_Champ-52'!L88&"-"&'12U_F_Champ-52'!C88&"-"&TEXT('12U_F_Champ-52'!B88,"h:mm am/pm") -> 12G-003-Group-7:00 AM | U4: 0.29166667 | V4: ='14U_F_Champ'!L18&"-"&'14U_F_Champ'!C18&"-"&TEXT('14U_F_Champ'!B18,"h:mm am/pm") -> 14G-001-Group-7:00 AM | W4: ='14U_F_Classic-39 from 40'!L40&"-"&'14U_F_Classic-39 from 40'!C40&"-"&TEXT('14U_F_Classic-39 from 40'!B40,"h:mm am/pm") -> 14GX-004-Group-7:00 AM | X4: ='14U_F_Classic-39 from 40'!L58&"-"&'14U_F_Classic-39 from 40'!C58&"-"&TEXT('14U_F_Classic-39 from 40'!B58,"h:mm am/pm") -> 14GX-002-Group-7:00 AM | Y4: ='14U_F_Classic-39 from 40'!L76&"-"&'14U_F_Classic-39 from 40'!C76&"-"&TEXT('14U_F_Classic-39 from 40'!B76,"h:mm am/pm") -> 14GX-001-Group-7:00 AM | Z4: 0.29166667 | AA4: ='14U_F_Classic-39 from 40'!L22&"-"&'14U_F_Classic-39 from 40'!C22&"-"&TEXT('14U_F_Classic-39 from 40'!B22,"h:mm am/pm") -> 14GX-003-Group-7:00 AM | AB4: ='14U_F_Champ'!L37&"-"&'14U_F_Champ'!C37&"-"&TEXT('14U_F_Champ'!B37,"h:mm am/pm") -> 14G-002-Group-7:00 AM | AC4: ='14U_F_Champ'!L56&"-"&'14U_F_Champ'!C56&"-"&TEXT('14U_F_Champ'!B56,"h:mm am/pm") -> 14G-003-Group-7:00 AM | AD4: ='14U_F_Champ'!L75&"-"&'14U_F_Champ'!C75&"-"&TEXT('14U_F_Champ'!B75,"h:mm am/pm") -> 14G-004-Group-7:00 AM | AF4: ='16U_F_Classic-45'!L38&"-"&'16U_F_Classic-45'!C38&"-"&TEXT('16U_F_Classic-45'!B38,"h:mm am/pm") -> 16GX-004-Group-7:00 AM | AG4: ='16U_F_Classic-45'!L20&"-"&'16U_F_Classic-45'!C20&"-"&TEXT('16U_F_Classic-45'!B20,"h:mm am/pm") -> 16GX-001-Group-7:00 AM | AH4: ='16U_F_Classic-45'!L75&"-"&'16U_F_Classic-45'!C75&"-"&TEXT('16U_F_Classic-45'!B75,"h:mm am/pm") -> 16GX-002-bracket-7:00 AM | AI4: ='16U_F_Classic-45'!L57&"-"&'16U_F_Classic-45'!C57&"-"&TEXT('16U_F_Classic-45'!B57,"h:mm am/pm") -> 16GX-003-bracket-7:00 AM | AJ4: ='16U_F_Champ'!L75&"-"&'16U_F_Champ'!C75&"-"&TEXT('16U_F_Champ'!B75,"h:mm am/pm") -> 16G-004-Group-7:00 AM | AK4: ='18U_F_Classic-44'!L20&"-"&'18U_F_Classic-44'!C20&"-"&TEXT('18U_F_Classic-44'!B20,"h:mm am/pm") -> 18GX-009-Group-7:00 AM | AL4: 0.29166667 | AM4: ='16U_F_Champ'!L18&"-"&'16U_F_Champ'!C18&"-"&TEXT('16U_F_Champ'!B18,"h:mm am/pm") -> 16G-001-Group-7:00 AM | AN4: ='16U_F_Champ'!L37&"-"&'16U_F_Champ'!C37&"-"&TEXT('16U_F_Champ'!B37,"h:mm am/pm") -> 16G-002-Group-7:00 AM | AO4: ='16U_F_Champ'!L56&"-"&'16U_F_Champ'!C56&"-"&TEXT('16U_F_Champ'!B56,"h:mm am/pm") -> 16G-003-Group-7:00 AM | AP4: ='18U_F_Classic-44'!L81&"-"&'18U_F_Classic-44'!C81&"-"&TEXT('18U_F_Classic-44'!B81,"h:mm am/pm") -> 18GX-004-Group-7:00 AM | AQ4: ='18U_F_Classic-44'!L40&"-"&'18U_F_Classic-44'!C40&"-"&TEXT('18U_F_Classic-44'!B40,"h:mm am/pm") -> 18GX-002-Group-7:00 AM | AR4: ='18U_F_Classic-44'!L61&"-"&'18U_F_Classic-44'!C61&"-"&TEXT('18U_F_Classic-44'!B61,"h:mm am/pm") -> 18GX-011-Group-7:00 AM | AU4: 0.29166667 | AV4: ='18U_F_Champ'!L50&"-"&'18U_F_Champ'!C50&"-"&TEXT('18U_F_Champ'!B50,"h:mm am/pm") -> 18G-004-Group-7:00 AM | AX4: ='18U_F_Champ'!L82&"-"&'18U_F_Champ'!C82&"-"&TEXT('18U_F_Champ'!B82,"h:mm am/pm") -> 18G-005-Group-7:00 AM | AY4: ='18U_F_Champ'!L18&"-"&'18U_F_Champ'!C18&"-"&TEXT('18U_F_Champ'!B18,"h:mm am/pm") -> 18G-001-Group-7:00 AM | AZ4: ='18U_F_Champ'!L66&"-"&'18U_F_Champ'!C66&"-"&TEXT('18U_F_Champ'!B66,"h:mm am/pm") -> 18G-003-Group-7:00 AM | BB4: ='18U_F_Champ'!L34&"-"&'18U_F_Champ'!C34&"-"&TEXT('18U_F_Champ'!B34,"h:mm am/pm") -> 18G-002-Group-7:00 AM
A5: 0.32638889 | B5: ='10U_Coed_Classic 22 from 23'!L31&"-"&'10U_Coed_Classic 22 from 23'!C31&"-"&TEXT('10U_Coed_Classic 22 from 23'!B31,"h:mm am/pm") -> 10CX-002-Group-7:50 AM | C5: ='10U_Coed_Champ_36'!L37&"-"&'10U_Coed_Champ_36'!C37&"-"&TEXT('10U_Coed_Champ_36'!B17,"h:mm am/pm") -> 10C-005-Group G-7:50 AM | E5: ='10U_Coed_Champ_36'!L17&"-"&'10U_Coed_Champ_36'!C17&"-"&TEXT('10U_Coed_Champ_36'!B17,"h:mm am/pm") -> 10C-004-Group B-7:50 AM | F5: ='10U_Coed_Champ_36'!L57&"-"&'10U_Coed_Champ_36'!C57&"-"&TEXT('10U_Coed_Champ_36'!B37,"h:mm am/pm") -> 10C-006-Group J-7:50 AM | I5: ='10U_Coed_Classic 22 from 23'!L13&"-"&'10U_Coed_Classic 22 from 23'!C13&"-"&TEXT('10U_Coed_Classic 22 from 23'!B13,"h:mm am/pm") -> 10CX-003-Group-7:50 AM | J5: 0.32638889 | K5: ='12U_Coed_Champ-45'!L21&"-"&'12U_Coed_Champ-45'!C21&"-"&TEXT('12U_Coed_Champ-45'!B21,"h:mm am/pm") -> 12C-005-Group-7:50 AM | L5: ='12U_Coed_Champ-45'!L39&"-"&'12U_Coed_Champ-45'!C39&"-"&TEXT('12U_Coed_Champ-45'!B39,"h:mm am/pm") -> 12C-008-Group-7:50 AM | M5: ='12U_Coed_Champ-45'!L58&"-"&'12U_Coed_Champ-45'!C58&"-"&TEXT('12U_Coed_Champ-45'!B58,"h:mm am/pm") -> 12C-011-Group-7:50 AM | N5: ='12U_Coed_Champ-45'!L76&"-"&'12U_Coed_Champ-45'!C76&"-"&TEXT('12U_Coed_Champ-45'!B76,"h:mm am/pm") -> 12C-010-Group-7:50 AM | O5: 0.32638889 | P5: ='12U_F_Champ-52'!L30&"-"&'12U_F_Champ-52'!C30&"-"&TEXT('12U_F_Champ-52'!B30,"h:mm am/pm") -> 12G-5A-Group-7:50 AM | Q5: ='12U_F_Champ-52'!L69&"-"&'12U_F_Champ-52'!C69&"-"&TEXT('12U_F_Champ-52'!B69,"h:mm am/pm") -> 12G-007-Group-7:50 AM | R5: ='12U_F_Champ-52'!L108&"-"&'12U_F_Champ-52'!C108&"-"&TEXT('12U_F_Champ-52'!B108,"h:mm am/pm") -> 12G-009-Group-7:50 AM | S5: ='12U_F_Champ-52'!L49&"-"&'12U_F_Champ-52'!C49&"-"&TEXT('12U_F_Champ-52'!B49,"h:mm am/pm") -> 12G-006-Group-7:50 AM | T5: ='12U_F_Champ-52'!L89&"-"&'12U_F_Champ-52'!C89&"-"&TEXT('12U_F_Champ-52'!B89,"h:mm am/pm") -> 12G-008-Group-7:50 AM | U5: 0.32638889 | V5: ='14U_F_Champ'!L19&"-"&'14U_F_Champ'!C19&"-"&TEXT('14U_F_Champ'!B19,"h:mm am/pm") -> 14G-005-Group-7:50 AM | W5: ='14U_F_Classic-39 from 40'!L41&"-"&'14U_F_Classic-39 from 40'!C41&"-"&TEXT('14U_F_Classic-39 from 40'!B41,"h:mm am/pm") -> 14GX-008-Group-7:50 AM | X5: ='14U_F_Classic-39 from 40'!L59&"-"&'14U_F_Classic-39 from 40'!C59&"-"&TEXT('14U_F_Classic-39 from 40'!B59,"h:mm am/pm") -> 14GX-006-Group-7:50 AM | Y5: ='14U_F_Classic-39 from 40'!L77&"-"&'14U_F_Classic-39 from 40'!C77&"-"&TEXT('14U_F_Classic-39 from 40'!B77,"h:mm am/pm") -> 14GX-005-Group-7:50 AM | Z5: 0.32638889 | AA5: ='14U_F_Classic-39 from 40'!L23&"-"&'14U_F_Classic-39 from 40'!C23&"-"&TEXT('14U_F_Classic-39 from 40'!B23,"h:mm am/pm") -> 14GX-007-Group-7:50 AM | AB5: ='14U_F_Champ'!L38&"-"&'14U_F_Champ'!C38&"-"&TEXT('14U_F_Champ'!B38,"h:mm am/pm") -> 14G-006-Group-7:50 AM | AC5: ='14U_F_Champ'!L57&"-"&'14U_F_Champ'!C57&"-"&TEXT('14U_F_Champ'!B57,"h:mm am/pm") -> 14G-007-Group-7:50 AM | AD5: ='14U_F_Champ'!L76&"-"&'14U_F_Champ'!C76&"-"&TEXT('14U_F_Champ'!B76,"h:mm am/pm") -> 14G-008-Group-7:50 AM | AF5: ='16U_F_Classic-45'!L39&"-"&'16U_F_Classic-45'!C39&"-"&TEXT('16U_F_Classic-45'!B39,"h:mm am/pm") -> 16GX-008-Group-7:50 AM | AG5: ='16U_F_Classic-45'!L21&"-"&'16U_F_Classic-45'!C21&"-"&TEXT('16U_F_Classic-45'!B21,"h:mm am/pm") -> 16GX-005-Group-7:50 AM | AH5: ='16U_F_Classic-45'!L76&"-"&'16U_F_Classic-45'!C76&"-"&TEXT('16U_F_Classic-45'!B76,"h:mm am/pm") -> 16GX-010-Group-7:50 AM | AI5: ='16U_F_Classic-45'!L58&"-"&'16U_F_Classic-45'!C58&"-"&TEXT('16U_F_Classic-45'!B58,"h:mm am/pm") -> 16GX-011-Group-7:50 AM | AJ5: ='16U_F_Champ'!L76&"-"&'16U_F_Champ'!C76&"-"&TEXT('16U_F_Champ'!B76,"h:mm am/pm") -> 16G-008-Group-7:50 AM | AK5: ='18U_F_Classic-44'!L21&"-"&'18U_F_Classic-44'!C21&"-"&TEXT('18U_F_Classic-44'!B21,"h:mm am/pm") -> 18GX-013-Group-7:50 AM | AL5: 0.32638889 | AM5: ='16U_F_Champ'!L19&"-"&'16U_F_Champ'!C19&"-"&TEXT('16U_F_Champ'!B19,"h:mm am/pm") -> 16G-005-Group-7:50 AM | AN5: ='16U_F_Champ'!L38&"-"&'16U_F_Champ'!C38&"-"&TEXT('16U_F_Champ'!B38,"h:mm am/pm") -> 16G-006-Group-7:50 AM | AO5: ='16U_F_Champ'!L57&"-"&'16U_F_Champ'!C57&"-"&TEXT('16U_F_Champ'!B57,"h:mm am/pm") -> 16G-007-Group-7:50 AM | AP5: ='18U_F_Classic-44'!L82&"-"&'18U_F_Classic-44'!C82&"-"&TEXT('18U_F_Classic-44'!B82,"h:mm am/pm") -> 18GX-008-Group-7:50 AM | AQ5: ='18U_F_Classic-44'!L41&"-"&'18U_F_Classic-44'!C41&"-"&TEXT('18U_F_Classic-44'!B41,"h:mm am/pm") -> 18GX-006-Group-7:50 AM | AR5: ='18U_F_Classic-44'!L62&"-"&'18U_F_Classic-44'!C62&"-"&TEXT('18U_F_Classic-44'!B62,"h:mm am/pm") -> 18GX-015-Group-7:50 AM | AU5: 0.33333333 | AV5: ='18U_F_Champ'!L51&"-"&'18U_F_Champ'!C51&"-"&TEXT('18U_F_Champ'!B51,"h:mm am/pm") -> 18G-008-Group-8:00 AM | AX5: ='18U_F_Champ'!L83&"-"&'18U_F_Champ'!C83&"-"&TEXT('18U_F_Champ'!B83,"h:mm am/pm") -> 18G-010-Group-8:00 AM | AY5: ='18U_F_Champ'!L19&"-"&'18U_F_Champ'!C19&"-"&TEXT('18U_F_Champ'!B19,"h:mm am/pm") -> 18G-006-Group-8:00 AM | AZ5: ='18U_F_Champ'!L67&"-"&'18U_F_Champ'!C67&"-"&TEXT('18U_F_Champ'!B67,"h:mm am/pm") -> 18G-009-Group-8:00 AM | BB5: ='18U_F_Champ'!L35&"-"&'18U_F_Champ'!C35&"-"&TEXT('18U_F_Champ'!B35,"h:mm am/pm") -> 18G-007-Group-8:00 AM
A6: 0.36111111 | B6: ='10U_Coed_Classic 22 from 23'!L32&"-"&'10U_Coed_Classic 22 from 23'!C32&"-"&TEXT('10U_Coed_Classic 22 from 23'!B32,"h:mm am/pm") -> 10CX-008-Group-8:40 AM | C6: ='10U_Coed_Champ_36'!L38&"-"&'10U_Coed_Champ_36'!C38&"-"&TEXT('10U_Coed_Champ_36'!B18,"h:mm am/pm") -> 10C-008-Group F-8:40 AM | D6: ='10U_F_Champ-18 teams'!L12&"-"&'10U_F_Champ-18 teams'!C12&"-"&TEXT('10U_F_Champ-18 teams'!B12,"h:mm am/pm") -> 10G-001-RR-8:40 AM | E6: ='10U_Coed_Champ_36'!L18&"-"&'10U_Coed_Champ_36'!C18&"-"&TEXT('10U_Coed_Champ_36'!B18,"h:mm am/pm") -> 10C-007-Group C-8:40 AM | F6: ='10U_Coed_Champ_36'!L58&"-"&'10U_Coed_Champ_36'!C58&"-"&TEXT('10U_Coed_Champ_36'!B38,"h:mm am/pm") -> 10C-009-Group K-8:40 AM | G6: ='10U_F_Champ-18 teams'!L28&"-"&'10U_F_Champ-18 teams'!C28&"-"&TEXT('10U_F_Champ-18 teams'!B28,"h:mm am/pm") -> 10G-002-RR-8:40 AM | I6: ='10U_Coed_Classic 22 from 23'!L14&"-"&'10U_Coed_Classic 22 from 23'!C14&"-"&TEXT('10U_Coed_Classic 22 from 23'!B14,"h:mm am/pm") -> 10CX-005-Group-8:40 AM | J6: 0.36111111 | K6: ='12U_Coed_Champ-45'!L22&"-"&'12U_Coed_Champ-45'!C22&"-"&TEXT('12U_Coed_Champ-45'!B22,"h:mm am/pm") -> 12C-009-Group-8:40 AM | L6: ='12U_Coed_Champ-45'!L40&"-"&'12U_Coed_Champ-45'!C40&"-"&TEXT('12U_Coed_Champ-45'!B40,"h:mm am/pm") -> 12C-012-Group-8:40 AM | M6: ='12U_Coed_Champ-45'!L59&"-"&'12U_Coed_Champ-45'!C59&"-"&TEXT('12U_Coed_Champ-45'!B59,"h:mm am/pm") -> 12C-015-Group-8:40 AM | N6: ='12U_Coed_Champ-45'!L77&"-"&'12U_Coed_Champ-45'!C77&"-"&TEXT('12U_Coed_Champ-45'!B77,"h:mm am/pm") -> 12C-014-Group-8:40 AM | O6: 0.36111111 | P6: ='12U_F_Champ-52'!L31&"-"&'12U_F_Champ-52'!C31&"-"&TEXT('12U_F_Champ-52'!B31,"h:mm am/pm") -> 12G-010-Group-8:40 AM | Q6: ='12U_F_Champ-52'!L70&"-"&'12U_F_Champ-52'!C70&"-"&TEXT('12U_F_Champ-52'!B70,"h:mm am/pm") -> 12G-012-Group-8:40 AM | R6: ='12U_F_Champ-52'!L109&"-"&'12U_F_Champ-52'!C109&"-"&TEXT('12U_F_Champ-52'!B109,"h:mm am/pm") -> 12G-014-Group-8:40 AM | S6: ='12U_F_Champ-52'!L50&"-"&'12U_F_Champ-52'!C50&"-"&TEXT('12U_F_Champ-52'!B50,"h:mm am/pm") -> 12G-011-Group-8:40 AM | T6: ='12U_F_Champ-52'!L90&"-"&'12U_F_Champ-52'!C90&"-"&TEXT('12U_F_Champ-52'!B90,"h:mm am/pm") -> 12G-013-Group-8:40 AM | U6: 0.36111111 | V6: ='14U_F_Champ'!L20&"-"&'14U_F_Champ'!C20&"-"&TEXT('14U_F_Champ'!B20,"h:mm am/pm") -> 14G-009-Group-8:40 AM | W6: ='14U_F_Classic-39 from 40'!L42&"-"&'14U_F_Classic-39 from 40'!C42&"-"&TEXT('14U_F_Classic-39 from 40'!B42,"h:mm am/pm") -> 14GX-012-Group-8:40 AM | X6: ='14U_F_Classic-39 from 40'!L60&"-"&'14U_F_Classic-39 from 40'!C60&"-"&TEXT('14U_F_Classic-39 from 40'!B60,"h:mm am/pm") -> 14GX-010-Group-8:40 AM | Y6: ='14U_F_Classic-39 from 40'!L78&"-"&'14U_F_Classic-39 from 40'!C78&"-"&TEXT('14U_F_Classic-39 from 40'!B78,"h:mm am/pm") -> 14GX-009-Group-8:40 AM | Z6: 0.36111111 | AA6: ='14U_F_Classic-39 from 40'!L24&"-"&'14U_F_Classic-39 from 40'!C24&"-"&TEXT('14U_F_Classic-39 from 40'!B24,"h:mm am/pm") -> 14GX-011-Group-8:40 AM | AB6: ='14U_F_Champ'!L39&"-"&'14U_F_Champ'!C39&"-"&TEXT('14U_F_Champ'!B39,"h:mm am/pm") -> 14G-010-Group-8:40 AM | AC6: ='14U_F_Champ'!L58&"-"&'14U_F_Champ'!C58&"-"&TEXT('14U_F_Champ'!B58,"h:mm am/pm") -> 14G-011-Group-8:40 AM | AD6: ='14U_F_Champ'!L77&"-"&'14U_F_Champ'!C77&"-"&TEXT('14U_F_Champ'!B77,"h:mm am/pm") -> 14G-012-Group-8:40 AM | AF6: ='16U_F_Classic-45'!L40&"-"&'16U_F_Classic-45'!C40&"-"&TEXT('16U_F_Classic-45'!B40,"h:mm am/pm") -> 16GX-012-Group-8:40 AM | AG6: ='16U_F_Classic-45'!L22&"-"&'16U_F_Classic-45'!C22&"-"&TEXT('16U_F_Classic-45'!B22,"h:mm am/pm") -> 16GX-009-Group-8:40 AM | AH6: ='16U_F_Classic-45'!L77&"-"&'16U_F_Classic-45'!C77&"-"&TEXT('16U_F_Classic-45'!B77,"h:mm am/pm") -> 16GX-014-Group-8:40 AM | AI6: ='16U_F_Classic-45'!L59&"-"&'16U_F_Classic-45'!C59&"-"&TEXT('16U_F_Classic-45'!B59,"h:mm am/pm") -> 16GX-015-Group-8:40 AM | AJ6: ='16U_F_Champ'!L77&"-"&'16U_F_Champ'!C77&"-"&TEXT('16U_F_Champ'!B77,"h:mm am/pm") -> 16G-012-Group-8:40 AM | AK6: ='18U_F_Classic-44'!L22&"-"&'18U_F_Classic-44'!C22&"-"&TEXT('18U_F_Classic-44'!B22,"h:mm am/pm") -> 18GX-001-Group-8:40 AM | AL6: 0.36111111 | AM6: ='16U_F_Champ'!L20&"-"&'16U_F_Champ'!C20&"-"&TEXT('16U_F_Champ'!B20,"h:mm am/pm") -> 16G-009-Group-8:40 AM | AN6: ='16U_F_Champ'!L39&"-"&'16U_F_Champ'!C39&"-"&TEXT('16U_F_Champ'!B39,"h:mm am/pm") -> 16G-010-Group-8:40 AM | AO6: ='16U_F_Champ'!L58&"-"&'16U_F_Champ'!C58&"-"&TEXT('16U_F_Champ'!B58,"h:mm am/pm") -> 16G-011-Group-8:40 AM | AP6: ='18U_F_Classic-44'!L83&"-"&'18U_F_Classic-44'!C83&"-"&TEXT('18U_F_Classic-44'!B83,"h:mm am/pm") -> 18GX-012-Group-8:40 AM | AQ6: ='18U_F_Classic-44'!L42&"-"&'18U_F_Classic-44'!C42&"-"&TEXT('18U_F_Classic-44'!B42,"h:mm am/pm") -> 18GX-010-Group-8:40 AM | AR6: ='18U_F_Classic-44'!L63&"-"&'18U_F_Classic-44'!C63&"-"&TEXT('18U_F_Classic-44'!B63,"h:mm am/pm") -> 18GX-003-Group-8:40 AM | AU6: 0.375 | AV6: ='18U_F_Champ'!L52&"-"&'18U_F_Champ'!C52&"-"&TEXT('18U_F_Champ'!B52,"h:mm am/pm") -> 18G-013-Group-9:00 AM | AX6: ='18U_F_Champ'!L84&"-"&'18U_F_Champ'!C84&"-"&TEXT('18U_F_Champ'!B84,"h:mm am/pm") -> 18G-015-Group-9:00 AM | AY6: ='18U_F_Champ'!L20&"-"&'18U_F_Champ'!C20&"-"&TEXT('18U_F_Champ'!B20,"h:mm am/pm") -> 18G-011-Group-9:00 AM | AZ6: ='18U_F_Champ'!L68&"-"&'18U_F_Champ'!C68&"-"&TEXT('18U_F_Champ'!B68,"h:mm am/pm") -> 18G-014-Group-9:00 AM | BB6: ='18U_F_Champ'!L36&"-"&'18U_F_Champ'!C36&"-"&TEXT('18U_F_Champ'!B36,"h:mm am/pm") -> 18G-012-Group-9:00 AM
A7: 0.39583333 | B7: ='10U_Coed_Classic 22 from 23'!L33&"-"&'10U_Coed_Classic 22 from 23'!C33&"-"&TEXT('10U_Coed_Classic 22 from 23'!B33,"h:mm am/pm") -> 10CX-004-Group-9:30 AM | C7: ='10U_Coed_Champ_36'!L39&"-"&'10U_Coed_Champ_36'!C39&"-"&TEXT('10U_Coed_Champ_36'!B19,"h:mm am/pm") -> 10C-011-Group E-9:30 AM | D7: ='10U_F_Champ-18 teams'!L13&"-"&'10U_F_Champ-18 teams'!C13&"-"&TEXT('10U_F_Champ-18 teams'!B13,"h:mm am/pm") -> 10G-003-RR-9:30 AM | E7: ='10U_Coed_Champ_36'!L19&"-"&'10U_Coed_Champ_36'!C19&"-"&TEXT('10U_Coed_Champ_36'!B19,"h:mm am/pm") -> 10C-010-Group D-9:30 AM | F7: ='10U_Coed_Champ_36'!L59&"-"&'10U_Coed_Champ_36'!C59&"-"&TEXT('10U_Coed_Champ_36'!B39,"h:mm am/pm") -> 10C-012-Group L-9:30 AM | G7: ='10U_F_Champ-18 teams'!L29&"-"&'10U_F_Champ-18 teams'!C29&"-"&TEXT('10U_F_Champ-18 teams'!B29,"h:mm am/pm") -> 10G-004-RR-9:30 AM | I7: ='10U_Coed_Classic 22 from 23'!L15&"-"&'10U_Coed_Classic 22 from 23'!C15&"-"&TEXT('10U_Coed_Classic 22 from 23'!B15,"h:mm am/pm") -> 10CX-007-Group-9:30 AM | J7: 0.39583333 | K7: ='12U_Coed_Champ-45'!L23&"-"&'12U_Coed_Champ-45'!C23&"-"&TEXT('12U_Coed_Champ-45'!B23,"h:mm am/pm") -> 12C-017-Group-9:30 AM | L7: ='12U_Coed_Champ-45'!L41&"-"&'12U_Coed_Champ-45'!C41&"-"&TEXT('12U_Coed_Champ-45'!B41,"h:mm am/pm") -> 12C-016-Group-9:30 AM | M7: ='12U_Coed_Champ-45'!L60&"-"&'12U_Coed_Champ-45'!C60&"-"&TEXT('12U_Coed_Champ-45'!B60,"h:mm am/pm") -> 12C-019-Group-9:30 AM | N7: ='12U_Coed_Champ-45'!L78&"-"&'12U_Coed_Champ-45'!C78&"-"&TEXT('12U_Coed_Champ-45'!B78,"h:mm am/pm") -> 12C-018-Group-9:30 AM | O7: 0.39583333 | P7: ='12U_F_Champ-52'!L32&"-"&'12U_F_Champ-52'!C32&"-"&TEXT('12U_F_Champ-52'!B32,"h:mm am/pm") -> 12G-015-Group-9:30 AM | Q7: ='12U_F_Champ-52'!L71&"-"&'12U_F_Champ-52'!C71&"-"&TEXT('12U_F_Champ-52'!B71,"h:mm am/pm") -> 12G-016-Group-9:30 AM | R7: ='12U_F_Champ-52'!L110&"-"&'12U_F_Champ-52'!C110&"-"&TEXT('12U_F_Champ-52'!B110,"h:mm am/pm") -> 12G-018-Group-9:30 AM | S7: ='12U_F_Champ-52'!L51&"-"&'12U_F_Champ-52'!C51&"-"&TEXT('12U_F_Champ-52'!B51,"h:mm am/pm") -> 12G-019-Group-9:30 AM | T7: ='12U_F_Champ-52'!L91&"-"&'12U_F_Champ-52'!C91&"-"&TEXT('12U_F_Champ-52'!B91,"h:mm am/pm") -> 12G-017-Group-9:30 AM | U7: 0.39583333 | V7: ='14U_F_Champ'!L21&"-"&'14U_F_Champ'!C21&"-"&TEXT('14U_F_Champ'!B21,"h:mm am/pm") -> 14G-013-Group-9:30 AM | W7: ='14U_F_Classic-39 from 40'!L43&"-"&'14U_F_Classic-39 from 40'!C43&"-"&TEXT('14U_F_Classic-39 from 40'!B43,"h:mm am/pm") -> 14GX-016-Group-9:30 AM | X7: ='14U_F_Classic-39 from 40'!L61&"-"&'14U_F_Classic-39 from 40'!C61&"-"&TEXT('14U_F_Classic-39 from 40'!B61,"h:mm am/pm") -> 14GX-014-Group-9:30 AM | Y7: ='14U_F_Classic-39 from 40'!L79&"-"&'14U_F_Classic-39 from 40'!C79&"-"&TEXT('14U_F_Classic-39 from 40'!B79,"h:mm am/pm") -> 14GX-013-Group-9:30 AM | Z7: 0.39583333 | AA7: ='14U_F_Classic-39 from 40'!L25&"-"&'14U_F_Classic-39 from 40'!C25&"-"&TEXT('14U_F_Classic-39 from 40'!B25,"h:mm am/pm") -> 14GX-015-Group-9:30 AM | AB7: ='14U_F_Champ'!L40&"-"&'14U_F_Champ'!C40&"-"&TEXT('14U_F_Champ'!B40,"h:mm am/pm") -> 14G-014-Group-9:30 AM | AC7: ='14U_F_Champ'!L59&"-"&'14U_F_Champ'!C59&"-"&TEXT('14U_F_Champ'!B59,"h:mm am/pm") -> 14G-015-Group-9:30 AM | AD7: ='14U_F_Champ'!L78&"-"&'14U_F_Champ'!C78&"-"&TEXT('14U_F_Champ'!B78,"h:mm am/pm") -> 14G-016-Group-9:30 AM | AF7: ='16U_F_Classic-45'!L41&"-"&'16U_F_Classic-45'!C41&"-"&TEXT('16U_F_Classic-45'!B41,"h:mm am/pm") -> 16GX-016-Group-9:30 AM | AG7: ='16U_F_Classic-45'!L23&"-"&'16U_F_Classic-45'!C23&"-"&TEXT('16U_F_Classic-45'!B23,"h:mm am/pm") -> 16GX-017-Group-9:30 AM | AH7: ='16U_F_Classic-45'!L78&"-"&'16U_F_Classic-45'!C78&"-"&TEXT('16U_F_Classic-45'!B78,"h:mm am/pm") -> 16GX-018-Group-9:30 AM | AI7: ='16U_F_Classic-45'!L60&"-"&'16U_F_Classic-45'!C60&"-"&TEXT('16U_F_Classic-45'!B60,"h:mm am/pm") -> 16GX-019-Group-9:30 AM | AJ7: ='16U_F_Champ'!L78&"-"&'16U_F_Champ'!C78&"-"&TEXT('16U_F_Champ'!B78,"h:mm am/pm") -> 16G-016-Group-9:30 AM | AK7: ='18U_F_Classic-44'!L23&"-"&'18U_F_Classic-44'!C23&"-"&TEXT('18U_F_Classic-44'!B23,"h:mm am/pm") -> 18GX-005-Group-9:30 AM | AL7: 0.39583333 | AM7: ='16U_F_Champ'!L21&"-"&'16U_F_Champ'!C21&"-"&TEXT('16U_F_Champ'!B21,"h:mm am/pm") -> 16G-013-Group-9:30 AM | AN7: ='16U_F_Champ'!L40&"-"&'16U_F_Champ'!C40&"-"&TEXT('16U_F_Champ'!B40,"h:mm am/pm") -> 16G-014-Group-9:30 AM | AO7: ='16U_F_Champ'!L59&"-"&'16U_F_Champ'!C59&"-"&TEXT('16U_F_Champ'!B59,"h:mm am/pm") -> 16G-015-Group-9:30 AM | AP7: ='18U_F_Classic-44'!L84&"-"&'18U_F_Classic-44'!C84&"-"&TEXT('18U_F_Classic-44'!B84,"h:mm am/pm") -> 18GX-016-Group-9:30 AM | AQ7: ='18U_F_Classic-44'!L43&"-"&'18U_F_Classic-44'!C43&"-"&TEXT('18U_F_Classic-44'!B43,"h:mm am/pm") -> 18GX-014-Group-9:30 AM | AR7: ='18U_F_Classic-44'!L64&"-"&'18U_F_Classic-44'!C64&"-"&TEXT('18U_F_Classic-44'!B64,"h:mm am/pm") -> 18GX-007-Group-9:30 AM | AU7: 0.41666667 | AV7: ='18U_F_Champ'!L53&"-"&'18U_F_Champ'!C53&"-"&TEXT('18U_F_Champ'!B53,"h:mm am/pm") -> 18G-018-Group-10:00 AM | AX7: ='18U_F_Champ'!L85&"-"&'18U_F_Champ'!C85&"-"&TEXT('18U_F_Champ'!B85,"h:mm am/pm") -> 18G-020-Group-10:00 AM | AY7: ='18U_F_Champ'!L21&"-"&'18U_F_Champ'!C21&"-"&TEXT('18U_F_Champ'!B21,"h:mm am/pm") -> 18G-016-Group-10:00 AM | AZ7: ='18U_F_Champ'!L69&"-"&'18U_F_Champ'!C69&"-"&TEXT('18U_F_Champ'!B69,"h:mm am/pm") -> 18G-019-Group-10:00 AM | BB7: ='18U_F_Champ'!L37&"-"&'18U_F_Champ'!C37&"-"&TEXT('18U_F_Champ'!B37,"h:mm am/pm") -> 18G-017-Group-10:00 AM
A8: 0.43055556 | B8: ='10U_Coed_Classic 22 from 23'!L34&"-"&'10U_Coed_Classic 22 from 23'!C34&"-"&TEXT('10U_Coed_Classic 22 from 23'!B34,"h:mm am/pm") -> 10CX-006-Group-10:20 AM | C8: ='10U_Coed_Champ_36'!L40&"-"&'10U_Coed_Champ_36'!C40&"-"&TEXT('10U_Coed_Champ_36'!B20,"h:mm am/pm") -> 10C-014-Group H-10:20 AM | D8: ='10U_F_Champ-18 teams'!L14&"-"&'10U_F_Champ-18 teams'!C14&"-"&TEXT('10U_F_Champ-18 teams'!B14,"h:mm am/pm") -> 10G-005-RR-10:20 AM | E8: ='10U_Coed_Champ_36'!L20&"-"&'10U_Coed_Champ_36'!C20&"-"&TEXT('10U_Coed_Champ_36'!B20,"h:mm am/pm") -> 10C-013-Group A-10:20 AM | F8: ='10U_Coed_Champ_36'!L60&"-"&'10U_Coed_Champ_36'!C60&"-"&TEXT('10U_Coed_Champ_36'!B40,"h:mm am/pm") -> 10C-015-Group I-10:20 AM | G8: ='10U_F_Champ-18 teams'!L30&"-"&'10U_F_Champ-18 teams'!C30&"-"&TEXT('10U_F_Champ-18 teams'!B30,"h:mm am/pm") -> 10G-006-RR-10:20 AM | I8: ='10U_Coed_Classic 22 from 23'!L16&"-"&'10U_Coed_Classic 22 from 23'!C16&"-"&TEXT('10U_Coed_Classic 22 from 23'!B16,"h:mm am/pm") -> 10CX-009-Group-10:20 AM | J8: 0.43055556 | K8: ='12U_Coed_Champ-45'!L24&"-"&'12U_Coed_Champ-45'!C24&"-"&TEXT('12U_Coed_Champ-45'!B24,"h:mm am/pm") -> 12C-021-Group-10:20 AM | L8: ='12U_Coed_Champ-45'!L42&"-"&'12U_Coed_Champ-45'!C42&"-"&TEXT('12U_Coed_Champ-45'!B42,"h:mm am/pm") -> 12C-020-Group-10:20 AM | M8: ='12U_Coed_Champ-45'!L61&"-"&'12U_Coed_Champ-45'!C61&"-"&TEXT('12U_Coed_Champ-45'!B61,"h:mm am/pm") -> 12C-027-bracket-10:20 AM | N8: ='12U_Coed_Champ-45'!L79&"-"&'12U_Coed_Champ-45'!C79&"-"&TEXT('12U_Coed_Champ-45'!B79,"h:mm am/pm") -> 12C-006-bracket-10:20 AM | O8: 0.43055556 | P8: ='12U_F_Champ-52'!L33&"-"&'12U_F_Champ-52'!C33&"-"&TEXT('12U_F_Champ-52'!B33,"h:mm am/pm") -> 12G-024-Group-10:20 AM | Q8: ='12U_F_Champ-52'!L72&"-"&'12U_F_Champ-52'!C72&"-"&TEXT('12U_F_Champ-52'!B72,"h:mm am/pm") -> 12G-021-Group-9:30 AM | R8: ='12U_F_Champ-52'!L111&"-"&'12U_F_Champ-52'!C111&"-"&TEXT('12U_F_Champ-52'!B111,"h:mm am/pm") -> 12G-023-Group-10:20 AM | S8: ='12U_F_Champ-52'!L52&"-"&'12U_F_Champ-52'!C52&"-"&TEXT('12U_F_Champ-52'!B52,"h:mm am/pm") -> 12G-020-Group-10:20 AM | T8: ='12U_F_Champ-52'!L92&"-"&'12U_F_Champ-52'!C92&"-"&TEXT('12U_F_Champ-52'!B92,"h:mm am/pm") -> 12G-022-Group-10:20 AM | U8: 0.43055556 | V8: ='14U_F_Champ'!L22&"-"&'14U_F_Champ'!C22&"-"&TEXT('14U_F_Champ'!B22,"h:mm am/pm") -> 14G-017-Group-10:20 AM | W8: ='14U_F_Classic-39 from 40'!L44&"-"&'14U_F_Classic-39 from 40'!C44&"-"&TEXT('14U_F_Classic-39 from 40'!B44,"h:mm am/pm") -> 14GX-020-Group-10:20 AM | X8: ='14U_F_Classic-39 from 40'!L62&"-"&'14U_F_Classic-39 from 40'!C62&"-"&TEXT('14U_F_Classic-39 from 40'!B62,"h:mm am/pm") -> 14GX-018-Group-10:20 AM | Y8: ='14U_F_Classic-39 from 40'!L80&"-"&'14U_F_Classic-39 from 40'!C80&"-"&TEXT('14U_F_Classic-39 from 40'!B80,"h:mm am/pm") -> 14GX-017-Group-10:20 AM | Z8: 0.43055556 | AA8: ='14U_F_Classic-39 from 40'!L26&"-"&'14U_F_Classic-39 from 40'!C26&"-"&TEXT('14U_F_Classic-39 from 40'!B26,"h:mm am/pm") -> 14GX-019-Group-10:20 AM | AB8: ='14U_F_Champ'!L41&"-"&'14U_F_Champ'!C41&"-"&TEXT('14U_F_Champ'!B41,"h:mm am/pm") -> 14G-018-Group-10:20 AM | AC8: ='14U_F_Champ'!L60&"-"&'14U_F_Champ'!C60&"-"&TEXT('14U_F_Champ'!B60,"h:mm am/pm") -> 14G-019-Group-10:20 AM | AD8: ='14U_F_Champ'!L79&"-"&'14U_F_Champ'!C79&"-"&TEXT('14U_F_Champ'!B79,"h:mm am/pm") -> 14G-020-Group-10:20 AM | AF8: ='16U_F_Classic-45'!L42&"-"&'16U_F_Classic-45'!C42&"-"&TEXT('16U_F_Classic-45'!B42,"h:mm am/pm") -> 16GX-020-Group-10:20 AM | AG8: ='16U_F_Classic-45'!L24&"-"&'16U_F_Classic-45'!C24&"-"&TEXT('16U_F_Classic-45'!B24,"h:mm am/pm") -> 16GX-021-Group-10:20 AM | AH8: ='16U_F_Classic-45'!L79&"-"&'16U_F_Classic-45'!C79&"-"&TEXT('16U_F_Classic-45'!B79,"h:mm am/pm") -> 16GX-006-bracket-10:20 AM | AI8: ='16U_F_Classic-45'!L61&"-"&'16U_F_Classic-45'!C61&"-"&TEXT('16U_F_Classic-45'!B61,"h:mm am/pm") -> 16GX-027-bracket-10:20 AM | AJ8: ='16U_F_Champ'!L79&"-"&'16U_F_Champ'!C79&"-"&TEXT('16U_F_Champ'!B79,"h:mm am/pm") -> 16G-020-Group-10:20 AM | AL8: 0.43055556 | AM8: ='16U_F_Champ'!L22&"-"&'16U_F_Champ'!C22&"-"&TEXT('16U_F_Champ'!B22,"h:mm am/pm") -> 16G-017-Group-10:20 AM | AN8: ='16U_F_Champ'!L41&"-"&'16U_F_Champ'!C41&"-"&TEXT('16U_F_Champ'!B41,"h:mm am/pm") -> 16G-018-Group-10:20 AM | AO8: ='16U_F_Champ'!L60&"-"&'16U_F_Champ'!C60&"-"&TEXT('16U_F_Champ'!B60,"h:mm am/pm") -> 16G-019-Group-10:20 AM | AP8: ='18U_F_Classic-44'!L85&"-"&'18U_F_Classic-44'!C85&"-"&TEXT('18U_F_Classic-44'!B85,"h:mm am/pm") -> 18GX-020-Group-10:20 AM | AQ8: ='18U_F_Classic-44'!L44&"-"&'18U_F_Classic-44'!C44&"-"&TEXT('18U_F_Classic-44'!B44,"h:mm am/pm") -> 18GX-018-Group-10:20 AM | AU8: 0.45833333 | AV8: ='18U_F_Champ'!L54&"-"&'18U_F_Champ'!C54&"-"&TEXT('18U_F_Champ'!B54,"h:mm am/pm") -> 18G-023-Group-11:00 AM | AX8: ='18U_F_Champ'!L86&"-"&'18U_F_Champ'!C86&"-"&TEXT('18U_F_Champ'!B86,"h:mm am/pm") -> 18G-025-Group-11:00 AM | AY8: ='18U_F_Champ'!L22&"-"&'18U_F_Champ'!C22&"-"&TEXT('18U_F_Champ'!B22,"h:mm am/pm") -> 18G-021-Group-11:00 AM | AZ8: ='18U_F_Champ'!L70&"-"&'18U_F_Champ'!C70&"-"&TEXT('18U_F_Champ'!B70,"h:mm am/pm") -> 18G-024-Group-11:00 AM | BB8: ='18U_F_Champ'!L38&"-"&'18U_F_Champ'!C38&"-"&TEXT('18U_F_Champ'!B38,"h:mm am/pm") -> 18G-022-Group-11:00 AM
A9: 0.46527778 | B9: ='10U_Coed_Classic 22 from 23'!L35&"-"&'10U_Coed_Classic 22 from 23'!C35&"-"&TEXT('10U_Coed_Classic 22 from 23'!B35,"h:mm am/pm") -> 10CX-012-Group-11:10 AM | C9: ='10U_Coed_Champ_36'!L41&"-"&'10U_Coed_Champ_36'!C41&"-"&TEXT('10U_Coed_Champ_36'!B21,"h:mm am/pm") -> 10C-017-Group G-11:10 AM | D9: ='10U_F_Champ-18 teams'!L15&"-"&'10U_F_Champ-18 teams'!C15&"-"&TEXT('10U_F_Champ-18 teams'!B15,"h:mm am/pm") -> 10G-007-RR-11:10 AM | E9: ='10U_Coed_Champ_36'!L21&"-"&'10U_Coed_Champ_36'!C21&"-"&TEXT('10U_Coed_Champ_36'!B21,"h:mm am/pm") -> 10C-016-Group B-11:10 AM | F9: ='10U_Coed_Champ_36'!L61&"-"&'10U_Coed_Champ_36'!C61&"-"&TEXT('10U_Coed_Champ_36'!B41,"h:mm am/pm") -> 10C-018-Group J-11:10 AM | G9: ='10U_F_Champ-18 teams'!L31&"-"&'10U_F_Champ-18 teams'!C31&"-"&TEXT('10U_F_Champ-18 teams'!B31,"h:mm am/pm") -> 10G-008-RR-11:10 AM | I9: ='10U_Coed_Classic 22 from 23'!L17&"-"&'10U_Coed_Classic 22 from 23'!C17&"-"&TEXT('10U_Coed_Classic 22 from 23'!B17,"h:mm am/pm") -> 10CX-011-Group-11:10 AM | J9: 0.46527778 | K9: ='12U_Coed_Champ-45'!L25&"-"&'12U_Coed_Champ-45'!C25&"-"&TEXT('12U_Coed_Champ-45'!B25,"h:mm am/pm") -> 12C-025-Group-11:10 AM | L9: ='12U_Coed_Champ-45'!L43&"-"&'12U_Coed_Champ-45'!C43&"-"&TEXT('12U_Coed_Champ-45'!B43,"h:mm am/pm") -> 12C-024-Group-11:10 AM | M9: ='12U_Coed_Champ-45'!L62&"-"&'12U_Coed_Champ-45'!C62&"-"&TEXT('12U_Coed_Champ-45'!B62,"h:mm am/pm") -> 12C-023-Group-11:10 AM | N9: ='12U_Coed_Champ-45'!L80&"-"&'12U_Coed_Champ-45'!C80&"-"&TEXT('12U_Coed_Champ-45'!B80,"h:mm am/pm") -> 12C-022-Group-11:10 AM | O9: 0.46527778 | P9: ='12U_F_Champ-52'!L34&"-"&'12U_F_Champ-52'!C34&"-"&TEXT('12U_F_Champ-52'!B34,"h:mm am/pm") -> 12G-043-Group-11:10 AM | Q9: ='12U_F_Champ-52'!L73&"-"&'12U_F_Champ-52'!C73&"-"&TEXT('12U_F_Champ-52'!B73,"h:mm am/pm") -> 12G-026-Group-10:20 AM | R9: ='12U_F_Champ-52'!L112&"-"&'12U_F_Champ-52'!C112&"-"&TEXT('12U_F_Champ-52'!B112,"h:mm am/pm") -> 12G-028-Group-11:10 AM | S9: ='12U_F_Champ-52'!L53&"-"&'12U_F_Champ-52'!C53&"-"&TEXT('12U_F_Champ-52'!B53,"h:mm am/pm") -> 12G-025-Group-11:10 AM | T9: ='12U_F_Champ-52'!L93&"-"&'12U_F_Champ-52'!C93&"-"&TEXT('12U_F_Champ-52'!B93,"h:mm am/pm") -> 12G-027-Group-11:10 AM | U9: 0.46527778 | V9: ='14U_F_Champ'!L23&"-"&'14U_F_Champ'!C23&"-"&TEXT('14U_F_Champ'!B23,"h:mm am/pm") -> 14G-021-Group-11:10 AM | W9: ='14U_F_Classic-39 from 40'!L45&"-"&'14U_F_Classic-39 from 40'!C45&"-"&TEXT('14U_F_Classic-39 from 40'!B45,"h:mm am/pm") -> 14GX-024-Group-11:10 AM | X9: ='14U_F_Classic-39 from 40'!L63&"-"&'14U_F_Classic-39 from 40'!C63&"-"&TEXT('14U_F_Classic-39 from 40'!B63,"h:mm am/pm") -> 14GX-022-Group-11:10 AM | Y9: ='14U_F_Classic-39 from 40'!L81&"-"&'14U_F_Classic-39 from 40'!C81&"-"&TEXT('14U_F_Classic-39 from 40'!B81,"h:mm am/pm") -> 14GX-021-Group-11:10 AM | Z9: 0.46527778 | AA9: ='14U_F_Classic-39 from 40'!L27&"-"&'14U_F_Classic-39 from 40'!C27&"-"&TEXT('14U_F_Classic-39 from 40'!B27,"h:mm am/pm") -> 14GX-023-Group-11:10 AM | AB9: ='14U_F_Champ'!L42&"-"&'14U_F_Champ'!C42&"-"&TEXT('14U_F_Champ'!B42,"h:mm am/pm") -> 14G-022-Group-11:10 AM | AC9: ='14U_F_Champ'!L61&"-"&'14U_F_Champ'!C61&"-"&TEXT('14U_F_Champ'!B61,"h:mm am/pm") -> 14G-023-Group-11:10 AM | AD9: ='14U_F_Champ'!L80&"-"&'14U_F_Champ'!C80&"-"&TEXT('14U_F_Champ'!B80,"h:mm am/pm") -> 14G-024-Group-11:10 AM | AF9: ='16U_F_Classic-45'!L43&"-"&'16U_F_Classic-45'!C43&"-"&TEXT('16U_F_Classic-45'!B43,"h:mm am/pm") -> 16GX-024-Group-11:10 AM | AG9: ='16U_F_Classic-45'!L25&"-"&'16U_F_Classic-45'!C25&"-"&TEXT('16U_F_Classic-45'!B25,"h:mm am/pm") -> 16GX-025-Group-11:10 AM | AH9: ='16U_F_Classic-45'!L80&"-"&'16U_F_Classic-45'!C80&"-"&TEXT('16U_F_Classic-45'!B80,"h:mm am/pm") -> 16GX-022-Group-11:10 AM | AI9: ='16U_F_Classic-45'!L62&"-"&'16U_F_Classic-45'!C62&"-"&TEXT('16U_F_Classic-45'!B62,"h:mm am/pm") -> 16GX-023-Group-11:10 AM | AJ9: ='16U_F_Champ'!L80&"-"&'16U_F_Champ'!C80&"-"&TEXT('16U_F_Champ'!B80,"h:mm am/pm") -> 16G-024-Group-11:10 AM | AK9: ='18U_F_Classic-44'!L25&"-"&'18U_F_Classic-44'!C25&"-"&TEXT('18U_F_Classic-44'!B25,"h:mm am/pm") -> 18GX-017-Group-11:10 AM | AL9: 0.46527778 | AM9: ='16U_F_Champ'!L23&"-"&'16U_F_Champ'!C23&"-"&TEXT('16U_F_Champ'!B23,"h:mm am/pm") -> 16G-021-Group-11:10 AM | AN9: ='16U_F_Champ'!L42&"-"&'16U_F_Champ'!C42&"-"&TEXT('16U_F_Champ'!B42,"h:mm am/pm") -> 16G-022-Group-11:10 AM | AO9: ='16U_F_Champ'!L61&"-"&'16U_F_Champ'!C61&"-"&TEXT('16U_F_Champ'!B61,"h:mm am/pm") -> 16G-023-Group-11:10 AM | AP9: ='18U_F_Classic-44'!L86&"-"&'18U_F_Classic-44'!C86&"-"&TEXT('18U_F_Classic-44'!B86,"h:mm am/pm") -> 18GX-024-Group-11:10 AM | AQ9: ='18U_F_Classic-44'!L45&"-"&'18U_F_Classic-44'!C45&"-"&TEXT('18U_F_Classic-44'!B45,"h:mm am/pm") -> 18GX-022-Group-11:10 AM | AR9: ='18U_F_Classic-44'!L66&"-"&'18U_F_Classic-44'!C66&"-"&TEXT('18U_F_Classic-44'!B66,"h:mm am/pm") -> 18GX-019-Group-11:10 AM | AU9: 0.5 | AV9: ='18U_F_Champ'!L55&"-"&'18U_F_Champ'!C55&"-"&TEXT('18U_F_Champ'!B55,"h:mm am/pm") -> 18G-029-Group-12:00 PM | AX9: ='18U_F_Champ'!L87&"-"&'18U_F_Champ'!C87&"-"&TEXT('18U_F_Champ'!B87,"h:mm am/pm") -> 18G-030-Group-12:00 PM | AY9: ='18U_F_Champ'!L23&"-"&'18U_F_Champ'!C23&"-"&TEXT('18U_F_Champ'!B23,"h:mm am/pm") -> 18G-026-Group-12:00 PM | AZ9: ='18U_F_Champ'!L71&"-"&'18U_F_Champ'!C71&"-"&TEXT('18U_F_Champ'!B71,"h:mm am/pm") -> 18G-028-Group-12:00 PM | BB9: ='18U_F_Champ'!L39&"-"&'18U_F_Champ'!C39&"-"&TEXT('18U_F_Champ'!B39,"h:mm am/pm") -> 18G-027-Group-12:00 PM
A10: 0.5 | B10: ='10U_Coed_Classic 22 from 23'!L36&"-"&'10U_Coed_Classic 22 from 23'!C36&"-"&TEXT('10U_Coed_Classic 22 from 23'!B36,"h:mm am/pm") -> 10CX-010-Group-12:00 PM | C10: ='10U_Coed_Champ_36'!L42&"-"&'10U_Coed_Champ_36'!C42&"-"&TEXT('10U_Coed_Champ_36'!B22,"h:mm am/pm") -> 10C-020-Group F-12:00 PM | D10: ='10U_F_Champ-18 teams'!L16&"-"&'10U_F_Champ-18 teams'!C16&"-"&TEXT('10U_F_Champ-18 teams'!B16,"h:mm am/pm") -> 10G-009-RR-12:00 PM | E10: ='10U_Coed_Champ_36'!L22&"-"&'10U_Coed_Champ_36'!C22&"-"&TEXT('10U_Coed_Champ_36'!B22,"h:mm am/pm") -> 10C-019-Group C-12:00 PM | F10: ='10U_Coed_Champ_36'!L62&"-"&'10U_Coed_Champ_36'!C62&"-"&TEXT('10U_Coed_Champ_36'!B42,"h:mm am/pm") -> 10C-021-Group K-12:00 PM | G10: ='10U_F_Champ-18 teams'!L32&"-"&'10U_F_Champ-18 teams'!C32&"-"&TEXT('10U_F_Champ-18 teams'!B32,"h:mm am/pm") -> 10G-010-RR-12:00 PM | I10: ='10U_Coed_Classic 22 from 23'!L18&"-"&'10U_Coed_Classic 22 from 23'!C18&"-"&TEXT('10U_Coed_Classic 22 from 23'!B18,"h:mm am/pm") -> 10CX-013-Group-12:00 PM | J10: 0.5 | K10: ='12U_Coed_Champ-45'!L26&"-"&'12U_Coed_Champ-45'!C26&"-"&TEXT('12U_Coed_Champ-45'!B26,"h:mm am/pm") -> 12C-033-Group-12:00 PM | L10: ='12U_Coed_Champ-45'!L44&"-"&'12U_Coed_Champ-45'!C44&"-"&TEXT('12U_Coed_Champ-45'!B44,"h:mm am/pm") -> 12C-028-Group-12:00 PM | M10: ='12U_Coed_Champ-45'!L63&"-"&'12U_Coed_Champ-45'!C63&"-"&TEXT('12U_Coed_Champ-45'!B63,"h:mm am/pm") -> 12C-035-Group-12:00 PM | N10: ='12U_Coed_Champ-45'!L81&"-"&'12U_Coed_Champ-45'!C81&"-"&TEXT('12U_Coed_Champ-45'!B81,"h:mm am/pm") -> 12C-034-Group-12:00 PM | O10: 0.5 | P10: ='12U_F_Champ-52'!L35&"-"&'12U_F_Champ-52'!C35&"-"&TEXT('12U_F_Champ-52'!B35,"h:mm am/pm") -> 12G-029-Group-12:00 PM | Q10: ='12U_F_Champ-52'!L74&"-"&'12U_F_Champ-52'!C74&"-"&TEXT('12U_F_Champ-52'!B74,"h:mm am/pm") -> 12G-031-Group-11:10 AM | R10: ='12U_F_Champ-52'!L113&"-"&'12U_F_Champ-52'!C113&"-"&TEXT('12U_F_Champ-52'!B113,"h:mm am/pm") -> 12G-033-Group-12:00 PM | S10: ='12U_F_Champ-52'!L54&"-"&'12U_F_Champ-52'!C54&"-"&TEXT('12U_F_Champ-52'!B54,"h:mm am/pm") -> 12G-030-Group-12:00 PM | T10: ='12U_F_Champ-52'!L94&"-"&'12U_F_Champ-52'!C94&"-"&TEXT('12U_F_Champ-52'!B94,"h:mm am/pm") -> 12G-032-Group-12:00 PM | U10: 0.5 | V10: ='14U_F_Champ'!L24&"-"&'14U_F_Champ'!C24&"-"&TEXT('14U_F_Champ'!B24,"h:mm am/pm") -> 14G-025-Group-12:00 PM | Z10: 0.5 | AB10: ='14U_F_Champ'!L43&"-"&'14U_F_Champ'!C43&"-"&TEXT('14U_F_Champ'!B43,"h:mm am/pm") -> 14G-026-Group-12:00 PM | AC10: ='14U_F_Champ'!L62&"-"&'14U_F_Champ'!C62&"-"&TEXT('14U_F_Champ'!B62,"h:mm am/pm") -> 14G-027-Group-12:00 PM | AD10: ='14U_F_Champ'!L81&"-"&'14U_F_Champ'!C81&"-"&TEXT('14U_F_Champ'!B81,"h:mm am/pm") -> 14G-028-Group-12:00 PM | AF10: ='16U_F_Classic-45'!L44&"-"&'16U_F_Classic-45'!C44&"-"&TEXT('16U_F_Classic-45'!B44,"h:mm am/pm") -> 16GX-028-Group-12:00 PM | AG10: ='16U_F_Classic-45'!L26&"-"&'16U_F_Classic-45'!C26&"-"&TEXT('16U_F_Classic-45'!B26,"h:mm am/pm") -> 16GX-033-Group-12:00 PM | AH10: ='16U_F_Classic-45'!L81&"-"&'16U_F_Classic-45'!C81&"-"&TEXT('16U_F_Classic-45'!B81,"h:mm am/pm") -> 16GX-034-Group-12:00 PM | AI10: ='16U_F_Classic-45'!L63&"-"&'16U_F_Classic-45'!C63&"-"&TEXT('16U_F_Classic-45'!B63,"h:mm am/pm") -> 16GX-035-Group-12:00 PM | AJ10: ='16U_F_Champ'!L81&"-"&'16U_F_Champ'!C81&"-"&TEXT('16U_F_Champ'!B81,"h:mm am/pm") -> 16G-028-Group-12:00 PM | AK10: ='18U_F_Classic-44'!L26&"-"&'18U_F_Classic-44'!C26&"-"&TEXT('18U_F_Classic-44'!B26,"h:mm am/pm") -> 18GX-021-Group-12:00 PM | AL10: 0.5 | AM10: ='16U_F_Champ'!L24&"-"&'16U_F_Champ'!C24&"-"&TEXT('16U_F_Champ'!B24,"h:mm am/pm") -> 16G-025-Group-12:00 PM | AN10: ='16U_F_Champ'!L43&"-"&'16U_F_Champ'!C43&"-"&TEXT('16U_F_Champ'!B43,"h:mm am/pm") -> 16G-026-Group-12:00 PM | AO10: ='16U_F_Champ'!L62&"-"&'16U_F_Champ'!C62&"-"&TEXT('16U_F_Champ'!B62,"h:mm am/pm") -> 16G-027-Group-12:00 PM | AP10: ='18U_F_Classic-44'!L87&"-"&'18U_F_Classic-44'!C87&"-"&TEXT('18U_F_Classic-44'!B87,"h:mm am/pm") -> 18GX-028-Group-12:00 PM | AQ10: ='18U_F_Classic-44'!L46&"-"&'18U_F_Classic-44'!C46&"-"&TEXT('18U_F_Classic-44'!B46,"h:mm am/pm") -> 18GX-026-Group-12:00 PM | AR10: ='18U_F_Classic-44'!L67&"-"&'18U_F_Classic-44'!C67&"-"&TEXT('18U_F_Classic-44'!B67,"h:mm am/pm") -> 18GX-023-Group-12:00 PM | AU10: 0.54166667 | AV10: ='18U_F_Champ'!L56&"-"&'18U_F_Champ'!C56&"-"&TEXT('18U_F_Champ'!B56,"h:mm am/pm") -> 18G-033-Group-1:00 PM | AX10: ='18U_F_Champ'!L88&"-"&'18U_F_Champ'!C88&"-"&TEXT('18U_F_Champ'!B88,"h:mm am/pm") -> 18G-035-Group-1:00 PM | AY10: ='18U_F_Champ'!L24&"-"&'18U_F_Champ'!C24&"-"&TEXT('18U_F_Champ'!B24,"h:mm am/pm") -> 18G-031-Group-1:00 PM | AZ10: ='18U_F_Champ'!L72&"-"&'18U_F_Champ'!C72&"-"&TEXT('18U_F_Champ'!B72,"h:mm am/pm") -> 18G-034-Group-1:00 PM | BB10: ='18U_F_Champ'!L40&"-"&'18U_F_Champ'!C40&"-"&TEXT('18U_F_Champ'!B40,"h:mm am/pm") -> 18G-032-Group-1:00 PM
A11: 0.53472222 | B11: ='10U_Coed_Classic 22 from 23'!L37&"-"&'10U_Coed_Classic 22 from 23'!C37&"-"&TEXT('10U_Coed_Classic 22 from 23'!B37,"h:mm am/pm") -> 10CX-014-Group-12:50 PM | C11: ='10U_Coed_Champ_36'!L43&"-"&'10U_Coed_Champ_36'!C43&"-"&TEXT('10U_Coed_Champ_36'!B23,"h:mm am/pm") -> 10C-023-Group E-12:50 PM | D11: ='10U_F_Champ-18 teams'!L17&"-"&'10U_F_Champ-18 teams'!C17&"-"&TEXT('10U_F_Champ-18 teams'!B17,"h:mm am/pm") -> 10G-011-RR-12:50 PM | E11: ='10U_Coed_Champ_36'!L23&"-"&'10U_Coed_Champ_36'!C23&"-"&TEXT('10U_Coed_Champ_36'!B23,"h:mm am/pm") -> 10C-022-Group D-12:50 PM | F11: ='10U_Coed_Champ_36'!L63&"-"&'10U_Coed_Champ_36'!C63&"-"&TEXT('10U_Coed_Champ_36'!B43,"h:mm am/pm") -> 10C-024-Group L-12:50 PM | G11: ='10U_F_Champ-18 teams'!L33&"-"&'10U_F_Champ-18 teams'!C33&"-"&TEXT('10U_F_Champ-18 teams'!B33,"h:mm am/pm") -> 10G-012-RR-12:50 PM | I11: ='10U_Coed_Classic 22 from 23'!L19&"-"&'10U_Coed_Classic 22 from 23'!C19&"-"&TEXT('10U_Coed_Classic 22 from 23'!B19,"h:mm am/pm") -> 10CX-015-Group-12:50 PM | J11: 0.53472222 | K11: ='12U_Coed_Champ-45'!L27&"-"&'12U_Coed_Champ-45'!C27&"-"&TEXT('12U_Coed_Champ-45'!B27,"h:mm am/pm") -> 12C-029-Group-12:50 PM | L11: ='12U_Coed_Champ-45'!L45&"-"&'12U_Coed_Champ-45'!C45&"-"&TEXT('12U_Coed_Champ-45'!B45,"h:mm am/pm") -> 12C-032-Group-12:50 PM | M11: ='12U_Coed_Champ-45'!L64&"-"&'12U_Coed_Champ-45'!C64&"-"&TEXT('12U_Coed_Champ-45'!B64,"h:mm am/pm") -> 12C-039-Group-12:50 PM | N11: ='12U_Coed_Champ-45'!L82&"-"&'12U_Coed_Champ-45'!C82&"-"&TEXT('12U_Coed_Champ-45'!B82,"h:mm am/pm") -> 12C-038-Group-12:50 PM | O11: 0.53472222 | P11: ='12U_F_Champ-52'!L36&"-"&'12U_F_Champ-52'!C36&"-"&TEXT('12U_F_Champ-52'!B36,"h:mm am/pm") -> 12G-034-Group-12:50 PM | Q11: ='12U_F_Champ-52'!L75&"-"&'12U_F_Champ-52'!C75&"-"&TEXT('12U_F_Champ-52'!B75,"h:mm am/pm") -> 12G-035-Group-12:00 PM | R11: ='12U_F_Champ-52'!L114&"-"&'12U_F_Champ-52'!C114&"-"&TEXT('12U_F_Champ-52'!B114,"h:mm am/pm") -> 12G-037-Group-12:50 PM | S11: ='12U_F_Champ-52'!L55&"-"&'12U_F_Champ-52'!C55&"-"&TEXT('12U_F_Champ-52'!B55,"h:mm am/pm") -> 12G-038-Group-12:50 PM | T11: ='12U_F_Champ-52'!L95&"-"&'12U_F_Champ-52'!C95&"-"&TEXT('12U_F_Champ-52'!B95,"h:mm am/pm") -> 12G-036-Group-12:50 PM | U11: 0.53472222 | V11: ='14U_F_Champ'!L25&"-"&'14U_F_Champ'!C25&"-"&TEXT('14U_F_Champ'!B25,"h:mm am/pm") -> 14G-029-Group-12:50 PM | W11: ='14U_F_Classic-39 from 40'!L47&"-"&'14U_F_Classic-39 from 40'!C47&"-"&TEXT('14U_F_Classic-39 from 40'!B47,"h:mm am/pm") -> 14GX-032-Group-12:50 PM | X11: ='14U_F_Classic-39 from 40'!L65&"-"&'14U_F_Classic-39 from 40'!C65&"-"&TEXT('14U_F_Classic-39 from 40'!B65,"h:mm am/pm") -> 14GX-026-Group-12:50 PM | Y11: ='14U_F_Classic-39 from 40'!L83&"-"&'14U_F_Classic-39 from 40'!C83&"-"&TEXT('14U_F_Classic-39 from 40'!B83,"h:mm am/pm") -> 14GX-025-Group-12:50 PM | Z11: 0.53472222 | AA11: ='14U_F_Classic-39 from 40'!L29&"-"&'14U_F_Classic-39 from 40'!C29&"-"&TEXT('14U_F_Classic-39 from 40'!B29,"h:mm am/pm") -> 14GX-031-Group-12:50 PM | AB11: ='14U_F_Champ'!L44&"-"&'14U_F_Champ'!C44&"-"&TEXT('14U_F_Champ'!B44,"h:mm am/pm") -> 14G-030-Group-12:50 PM | AC11: ='14U_F_Champ'!L63&"-"&'14U_F_Champ'!C63&"-"&TEXT('14U_F_Champ'!B63,"h:mm am/pm") -> 14G-031-Group-12:50 PM | AD11: ='14U_F_Champ'!L82&"-"&'14U_F_Champ'!C82&"-"&TEXT('14U_F_Champ'!B82,"h:mm am/pm") -> 14G-032-Group-12:50 PM | AF11: ='16U_F_Classic-45'!L45&"-"&'16U_F_Classic-45'!C45&"-"&TEXT('16U_F_Classic-45'!B45,"h:mm am/pm") -> 16GX-032-Group-12:50 PM | AG11: ='16U_F_Classic-45'!L27&"-"&'16U_F_Classic-45'!C27&"-"&TEXT('16U_F_Classic-45'!B27,"h:mm am/pm") -> 16GX-029-Group-12:50 PM | AH11: ='16U_F_Classic-45'!L82&"-"&'16U_F_Classic-45'!C82&"-"&TEXT('16U_F_Classic-45'!B82,"h:mm am/pm") -> 16GX-038-Group-12:50 PM | AI11: ='16U_F_Classic-45'!L64&"-"&'16U_F_Classic-45'!C64&"-"&TEXT('16U_F_Classic-45'!B64,"h:mm am/pm") -> 16GX-039-Group-12:50 PM | AJ11: ='16U_F_Champ'!L82&"-"&'16U_F_Champ'!C82&"-"&TEXT('16U_F_Champ'!B82,"h:mm am/pm") -> 16G-032-Group-12:50 PM | AK11: ='18U_F_Classic-44'!L27&"-"&'18U_F_Classic-44'!C27&"-"&TEXT('18U_F_Classic-44'!B27,"h:mm am/pm") -> 18GX-025-Group-12:50 PM | AL11: 0.53472222 | AM11: ='16U_F_Champ'!L25&"-"&'16U_F_Champ'!C25&"-"&TEXT('16U_F_Champ'!B25,"h:mm am/pm") -> 16G-029-Group-12:50 PM | AN11: ='16U_F_Champ'!L44&"-"&'16U_F_Champ'!C44&"-"&TEXT('16U_F_Champ'!B44,"h:mm am/pm") -> 16G-030-Group-12:50 PM | AO11: ='16U_F_Champ'!L63&"-"&'16U_F_Champ'!C63&"-"&TEXT('16U_F_Champ'!B63,"h:mm am/pm") -> 16G-031-Group-12:50 PM | AP11: ='18U_F_Classic-44'!L88&"-"&'18U_F_Classic-44'!C88&"-"&TEXT('18U_F_Classic-44'!B88,"h:mm am/pm") -> 18GX-032-Group-12:50 PM | AQ11: ='18U_F_Classic-44'!L47&"-"&'18U_F_Classic-44'!C47&"-"&TEXT('18U_F_Classic-44'!B47,"h:mm am/pm") -> 18GX-030-Group-12:50 PM | AR11: ='18U_F_Classic-44'!L68&"-"&'18U_F_Classic-44'!C68&"-"&TEXT('18U_F_Classic-44'!B68,"h:mm am/pm") -> 18GX-027-Group-12:50 PM | AU11: 0.58333333 | AV11: ='18U_F_Champ'!L57&"-"&'18U_F_Champ'!C57&"-"&TEXT('18U_F_Champ'!B57,"h:mm am/pm") -> 18G-038-Group-2:00 PM | AX11: ='18U_F_Champ'!L89&"-"&'18U_F_Champ'!C89&"-"&TEXT('18U_F_Champ'!B89,"h:mm am/pm") -> 18G-040-Group-2:00 PM | AY11: ='18U_F_Champ'!L25&"-"&'18U_F_Champ'!C25&"-"&TEXT('18U_F_Champ'!B25,"h:mm am/pm") -> 18G-036-Group-2:00 PM | AZ11: ='18U_F_Champ'!L73&"-"&'18U_F_Champ'!C73&"-"&TEXT('18U_F_Champ'!B73,"h:mm am/pm") -> 18G-039-Group-2:00 PM | BB11: ='18U_F_Champ'!L41&"-"&'18U_F_Champ'!C41&"-"&TEXT('18U_F_Champ'!B41,"h:mm am/pm") -> 18G-037-Group-2:00 PM
A12: 0.56944444 | B12: ='10U_Coed_Classic 22 from 23'!L38&"-"&'10U_Coed_Classic 22 from 23'!C38&"-"&TEXT('10U_Coed_Classic 22 from 23'!B38,"h:mm am/pm") -> 10CX-016-Group-1:40 PM | C12: ='10U_Coed_Champ_36'!L44&"-"&'10U_Coed_Champ_36'!C44&"-"&TEXT('10U_Coed_Champ_36'!B24,"h:mm am/pm") -> 10C-026-Group H-1:40 PM | D12: ='10U_F_Champ-18 teams'!L18&"-"&'10U_F_Champ-18 teams'!C18&"-"&TEXT('10U_F_Champ-18 teams'!B18,"h:mm am/pm") -> 10G-013-RR-1:40 PM | E12: ='10U_Coed_Champ_36'!L24&"-"&'10U_Coed_Champ_36'!C24&"-"&TEXT('10U_Coed_Champ_36'!B24,"h:mm am/pm") -> 10C-025-Group A-1:40 PM | F12: ='10U_Coed_Champ_36'!L64&"-"&'10U_Coed_Champ_36'!C64&"-"&TEXT('10U_Coed_Champ_36'!B44,"h:mm am/pm") -> 10C-027-Group I-1:40 PM | G12: ='10U_F_Champ-18 teams'!L34&"-"&'10U_F_Champ-18 teams'!C34&"-"&TEXT('10U_F_Champ-18 teams'!B34,"h:mm am/pm") -> 10G-014-RR-1:40 PM | I12: ='10U_Coed_Classic 22 from 23'!L20&"-"&'10U_Coed_Classic 22 from 23'!C20&"-"&TEXT('10U_Coed_Classic 22 from 23'!B20,"h:mm am/pm") -> 10CX-017-Group-1:40 PM | J12: 0.56944444 | K12: ='12U_Coed_Champ-45'!L28&"-"&'12U_Coed_Champ-45'!C28&"-"&TEXT('12U_Coed_Champ-45'!B28,"h:mm am/pm") -> 12C-041-Group-1:40 PM | L12: ='12U_Coed_Champ-45'!L46&"-"&'12U_Coed_Champ-45'!C46&"-"&TEXT('12U_Coed_Champ-45'!B46,"h:mm am/pm") -> 12C-036-Group-1:40 PM | M12: ='12U_Coed_Champ-45'!L65&"-"&'12U_Coed_Champ-45'!C65&"-"&TEXT('12U_Coed_Champ-45'!B65,"h:mm am/pm") -> 12C-031-bracket-1:40 PM | N12: ='12U_Coed_Champ-45'!L83&"-"&'12U_Coed_Champ-45'!C83&"-"&TEXT('12U_Coed_Champ-45'!B83,"h:mm am/pm") -> 12C-026-bracket-1:40 PM | O12: 0.56944444 | P12: ='12U_F_Champ-52'!L37&"-"&'12U_F_Champ-52'!C37&"-"&TEXT('12U_F_Champ-52'!B37,"h:mm am/pm") -> 12G-53A-Group-1:40 PM | Q12: ='12U_F_Champ-52'!L76&"-"&'12U_F_Champ-52'!C76&"-"&TEXT('12U_F_Champ-52'!B76,"h:mm am/pm") -> 12G-040-Group-12:50 PM | R12: ='12U_F_Champ-52'!L115&"-"&'12U_F_Champ-52'!C115&"-"&TEXT('12U_F_Champ-52'!B115,"h:mm am/pm") -> 12G-042-Group-1:40 PM | S12: ='12U_F_Champ-52'!L56&"-"&'12U_F_Champ-52'!C56&"-"&TEXT('12U_F_Champ-52'!B56,"h:mm am/pm") -> 12G-039-Group-1:40 PM | T12: ='12U_F_Champ-52'!L96&"-"&'12U_F_Champ-52'!C96&"-"&TEXT('12U_F_Champ-52'!B96,"h:mm am/pm") -> 12G-041-Group-1:40 PM | U12: 0.56944444 | V12: ='14U_F_Champ'!L26&"-"&'14U_F_Champ'!C26&"-"&TEXT('14U_F_Champ'!B26,"h:mm am/pm") -> 14G-033-Group-1:40 PM | W12: ='14U_F_Classic-39 from 40'!L48&"-"&'14U_F_Classic-39 from 40'!C48&"-"&TEXT('14U_F_Classic-39 from 40'!B48,"h:mm am/pm") -> 14GX-036-Group-1:40 PM | X12: ='14U_F_Classic-39 from 40'!L66&"-"&'14U_F_Classic-39 from 40'!C66&"-"&TEXT('14U_F_Classic-39 from 40'!B66,"h:mm am/pm") -> 14GX-030-Group-1:40 PM | Y12: ='14U_F_Classic-39 from 40'!L84&"-"&'14U_F_Classic-39 from 40'!C84&"-"&TEXT('14U_F_Classic-39 from 40'!B84,"h:mm am/pm") -> 14GX-033-Group-1:40 PM | Z12: 0.56944444 | AA12: ='14U_F_Classic-39 from 40'!L30&"-"&'14U_F_Classic-39 from 40'!C30&"-"&TEXT('14U_F_Classic-39 from 40'!B30,"h:mm am/pm") -> 14GX-035-Group-1:40 PM | AB12: ='14U_F_Champ'!L45&"-"&'14U_F_Champ'!C45&"-"&TEXT('14U_F_Champ'!B45,"h:mm am/pm") -> 14G-034-Group-1:40 PM | AC12: ='14U_F_Champ'!L64&"-"&'14U_F_Champ'!C64&"-"&TEXT('14U_F_Champ'!B64,"h:mm am/pm") -> 14G-035-Group-1:40 PM | AD12: ='14U_F_Champ'!L83&"-"&'14U_F_Champ'!C83&"-"&TEXT('14U_F_Champ'!B83,"h:mm am/pm") -> 14G-036-Group-1:40 PM | AF12: ='16U_F_Classic-45'!L46&"-"&'16U_F_Classic-45'!C46&"-"&TEXT('16U_F_Classic-45'!B46,"h:mm am/pm") -> 16GX-036-Group-1:40 PM | AG12: ='16U_F_Classic-45'!L28&"-"&'16U_F_Classic-45'!C28&"-"&TEXT('16U_F_Classic-45'!B28,"h:mm am/pm") -> 16GX-041-Group-1:40 PM | AH12: ='16U_F_Classic-45'!L83&"-"&'16U_F_Classic-45'!C83&"-"&TEXT('16U_F_Classic-45'!B83,"h:mm am/pm") -> 16GX-026-bracket-1:40 PM | AI12: ='16U_F_Classic-45'!L65&"-"&'16U_F_Classic-45'!C65&"-"&TEXT('16U_F_Classic-45'!B65,"h:mm am/pm") -> 16GX-031-bracket-1:40 PM | AJ12: ='16U_F_Champ'!L83&"-"&'16U_F_Champ'!C83&"-"&TEXT('16U_F_Champ'!B83,"h:mm am/pm") -> 16G-036-Group-1:40 PM | AK12: ='18U_F_Classic-44'!L28&"-"&'18U_F_Classic-44'!C28&"-"&TEXT('18U_F_Classic-44'!B28,"h:mm am/pm") -> 18GX-029-Group-1:40 PM | AL12: 0.56944444 | AM12: ='16U_F_Champ'!L26&"-"&'16U_F_Champ'!C26&"-"&TEXT('16U_F_Champ'!B26,"h:mm am/pm") -> 16G-033-Group-1:40 PM | AN12: ='16U_F_Champ'!L45&"-"&'16U_F_Champ'!C45&"-"&TEXT('16U_F_Champ'!B45,"h:mm am/pm") -> 16G-034-Group-1:40 PM | AO12: ='16U_F_Champ'!L64&"-"&'16U_F_Champ'!C64&"-"&TEXT('16U_F_Champ'!B64,"h:mm am/pm") -> 16G-035-Group-1:40 PM | AP12: ='18U_F_Classic-44'!L89&"-"&'18U_F_Classic-44'!C89&"-"&TEXT('18U_F_Classic-44'!B89,"h:mm am/pm") -> 18GX-036-Group-1:40 PM | AQ12: ='18U_F_Classic-44'!L48&"-"&'18U_F_Classic-44'!C48&"-"&TEXT('18U_F_Classic-44'!B48,"h:mm am/pm") -> 18GX-034-Group-1:40 PM | AR12: ='18U_F_Classic-44'!L69&"-"&'18U_F_Classic-44'!C69&"-"&TEXT('18U_F_Classic-44'!B69,"h:mm am/pm") -> 18GX-031-Group-1:40 PM | AU12: 0.625 | AV12: ='18U_F_Champ'!L58&"-"&'18U_F_Champ'!C58&"-"&TEXT('18U_F_Champ'!B58,"h:mm am/pm") -> 18G-043-Group-3:00 PM | AY12: ='18U_F_Champ'!L26&"-"&'18U_F_Champ'!C26&"-"&TEXT('18U_F_Champ'!B26,"h:mm am/pm") -> 18G-041-Group-3:00 PM | AZ12: ='18U_F_Champ'!L74&"-"&'18U_F_Champ'!C74&"-"&TEXT('18U_F_Champ'!B74,"h:mm am/pm") -> 18G-044-Group-3:00 PM | BB12: ='18U_F_Champ'!L42&"-"&'18U_F_Champ'!C42&"-"&TEXT('18U_F_Champ'!B42,"h:mm am/pm") -> 18G-042-Group-3:00 PM
A13: 0.60416667 | B13: ='10U_Coed_Classic 22 from 23'!L39&"-"&'10U_Coed_Classic 22 from 23'!C39&"-"&TEXT('10U_Coed_Classic 22 from 23'!B39,"h:mm am/pm") -> 10CX-020-Group-2:30 PM | C13: ='10U_Coed_Champ_36'!L45&"-"&'10U_Coed_Champ_36'!C45&"-"&TEXT('10U_Coed_Champ_36'!B25,"h:mm am/pm") -> 10C-029-Group G-2:30 PM | D13: ='10U_F_Champ-18 teams'!L19&"-"&'10U_F_Champ-18 teams'!C19&"-"&TEXT('10U_F_Champ-18 teams'!B19,"h:mm am/pm") -> 10G-015-RR-2:30 PM | E13: ='10U_Coed_Champ_36'!L25&"-"&'10U_Coed_Champ_36'!C25&"-"&TEXT('10U_Coed_Champ_36'!B25,"h:mm am/pm") -> 10C-028-Group B-2:30 PM | F13: ='10U_Coed_Champ_36'!L65&"-"&'10U_Coed_Champ_36'!C65&"-"&TEXT('10U_Coed_Champ_36'!B45,"h:mm am/pm") -> 10C-030-Group J-2:30 PM | G13: ='10U_F_Champ-18 teams'!L35&"-"&'10U_F_Champ-18 teams'!C35&"-"&TEXT('10U_F_Champ-18 teams'!B35,"h:mm am/pm") -> 10G-016-RR-2:30 PM | I13: ='10U_Coed_Classic 22 from 23'!L21&"-"&'10U_Coed_Classic 22 from 23'!C21&"-"&TEXT('10U_Coed_Classic 22 from 23'!B21,"h:mm am/pm") -> 10CX-019-Group-2:30 PM | J13: 0.60416667 | K13: ='12U_Coed_Champ-45'!L29&"-"&'12U_Coed_Champ-45'!C29&"-"&TEXT('12U_Coed_Champ-45'!B29,"h:mm am/pm") -> 12C-045-Group-2:30 PM | L13: ='12U_Coed_Champ-45'!L47&"-"&'12U_Coed_Champ-45'!C47&"-"&TEXT('12U_Coed_Champ-45'!B47,"h:mm am/pm") -> 12C-040-Group-2:30 PM | M13: ='12U_Coed_Champ-45'!L66&"-"&'12U_Coed_Champ-45'!C66&"-"&TEXT('12U_Coed_Champ-45'!B66,"h:mm am/pm") -> 12C-043-Group-2:30 PM | N13: ='12U_Coed_Champ-45'!L84&"-"&'12U_Coed_Champ-45'!C84&"-"&TEXT('12U_Coed_Champ-45'!B84,"h:mm am/pm") -> 12C-042-Group-2:30 PM | O13: 0.60416667 | P13: ='12U_F_Champ-52'!L38&"-"&'12U_F_Champ-52'!C38&"-"&TEXT('12U_F_Champ-52'!B38,"h:mm am/pm") -> 12G-53B-Group-2:30 PM | Q13: ='12U_F_Champ-52'!L77&"-"&'12U_F_Champ-52'!C77&"-"&TEXT('12U_F_Champ-52'!B77,"h:mm am/pm") -> 12G-045-Group-1:40 PM | R13: ='12U_F_Champ-52'!L116&"-"&'12U_F_Champ-52'!C116&"-"&TEXT('12U_F_Champ-52'!B116,"h:mm am/pm") -> 12G-047-Group-2:30 PM | S13: ='12U_F_Champ-52'!L57&"-"&'12U_F_Champ-52'!C57&"-"&TEXT('12U_F_Champ-52'!B57,"h:mm am/pm") -> 12G-044-Group-2:30 PM | T13: ='12U_F_Champ-52'!L97&"-"&'12U_F_Champ-52'!C97&"-"&TEXT('12U_F_Champ-52'!B97,"h:mm am/pm") -> 12G-046-Group-2:30 PM | U13: 0.60416667 | V13: ='14U_F_Champ'!L27&"-"&'14U_F_Champ'!C27&"-"&TEXT('14U_F_Champ'!B27,"h:mm am/pm") -> 14G-037-Group-2:30 PM | W13: ='14U_F_Classic-39 from 40'!L49&"-"&'14U_F_Classic-39 from 40'!C49&"-"&TEXT('14U_F_Classic-39 from 40'!B49,"h:mm am/pm") -> 14GX-040-Group-2:30 PM | X13: ='14U_F_Classic-39 from 40'!L67&"-"&'14U_F_Classic-39 from 40'!C67&"-"&TEXT('14U_F_Classic-39 from 40'!B67,"h:mm am/pm") -> 14GX-034-Group-2:30 PM | Y13: ='14U_F_Classic-39 from 40'!L85&"-"&'14U_F_Classic-39 from 40'!C85&"-"&TEXT('14U_F_Classic-39 from 40'!B85,"h:mm am/pm") -> 14GX-037-Group-2:30 PM | Z13: 0.60416667 | AA13: ='14U_F_Classic-39 from 40'!L31&"-"&'14U_F_Classic-39 from 40'!C31&"-"&TEXT('14U_F_Classic-39 from 40'!B31,"h:mm am/pm") -> 14GX-039-Group-2:30 PM | AB13: ='14U_F_Champ'!L46&"-"&'14U_F_Champ'!C46&"-"&TEXT('14U_F_Champ'!B46,"h:mm am/pm") -> 14G-038-Group-2:30 PM | AC13: ='14U_F_Champ'!L65&"-"&'14U_F_Champ'!C65&"-"&TEXT('14U_F_Champ'!B65,"h:mm am/pm") -> 14G-039-Group-2:30 PM | AD13: ='14U_F_Champ'!L84&"-"&'14U_F_Champ'!C84&"-"&TEXT('14U_F_Champ'!B84,"h:mm am/pm") -> 14G-040-Group-2:30 PM | AF13: ='16U_F_Classic-45'!L47&"-"&'16U_F_Classic-45'!C47&"-"&TEXT('16U_F_Classic-45'!B47,"h:mm am/pm") -> 16GX-040-Group-2:30 PM | AG13: ='16U_F_Classic-45'!L29&"-"&'16U_F_Classic-45'!C29&"-"&TEXT('16U_F_Classic-45'!B29,"h:mm am/pm") -> 16GX-045-Group-2:30 PM | AH13: ='16U_F_Classic-45'!L84&"-"&'16U_F_Classic-45'!C84&"-"&TEXT('16U_F_Classic-45'!B84,"h:mm am/pm") -> 16GX-042-Group-2:30 PM | AI13: ='16U_F_Classic-45'!L66&"-"&'16U_F_Classic-45'!C66&"-"&TEXT('16U_F_Classic-45'!B66,"h:mm am/pm") -> 16GX-043-Group-2:30 PM | AJ13: ='16U_F_Champ'!L84&"-"&'16U_F_Champ'!C84&"-"&TEXT('16U_F_Champ'!B84,"h:mm am/pm") -> 16G-040-Group-2:30 PM | AL13: 0.60416667 | AM13: ='16U_F_Champ'!L27&"-"&'16U_F_Champ'!C27&"-"&TEXT('16U_F_Champ'!B27,"h:mm am/pm") -> 16G-037-Group-2:30 PM | AN13: ='16U_F_Champ'!L46&"-"&'16U_F_Champ'!C46&"-"&TEXT('16U_F_Champ'!B46,"h:mm am/pm") -> 16G-038-Group-2:30 PM | AO13: ='16U_F_Champ'!L65&"-"&'16U_F_Champ'!C65&"-"&TEXT('16U_F_Champ'!B65,"h:mm am/pm") -> 16G-039-Group-2:30 PM | AP13: ='18U_F_Classic-44'!L90&"-"&'18U_F_Classic-44'!C90&"-"&TEXT('18U_F_Classic-44'!B90,"h:mm am/pm") -> 18GX-040-Group-2:30 PM | AQ13: ='18U_F_Classic-44'!L49&"-"&'18U_F_Classic-44'!C49&"-"&TEXT('18U_F_Classic-44'!B49,"h:mm am/pm") -> 18GX-038-Group-2:30 PM | AU13: 0.66666667 | AV13: ='18U_F_Champ'!L59&"-"&'18U_F_Champ'!C59&"-"&TEXT('18U_F_Champ'!B59,"h:mm am/pm") -> 18G-047-Group-4:00 PM | AX13: ='18U_F_Champ'!L91&"-"&'18U_F_Champ'!C91&"-"&TEXT('18U_F_Champ'!B91,"h:mm am/pm") -> 18G-049-2-3 cross-4:00 PM | AY13: ='18U_F_Champ'!L27&"-"&'18U_F_Champ'!C27&"-"&TEXT('18U_F_Champ'!B27,"h:mm am/pm") -> 18G-045-Group-4:00 PM | AZ13: ='18U_F_Champ'!L75&"-"&'18U_F_Champ'!C75&"-"&TEXT('18U_F_Champ'!B75,"h:mm am/pm") -> 18G-048-Group-4:00 PM | BB13: ='18U_F_Champ'!L43&"-"&'18U_F_Champ'!C43&"-"&TEXT('18U_F_Champ'!B43,"h:mm am/pm") -> 18G-046-Group-4:00 PM
A14: 0.63888889 | B14: ='10U_Coed_Classic 22 from 23'!L40&"-"&'10U_Coed_Classic 22 from 23'!C40&"-"&TEXT('10U_Coed_Classic 22 from 23'!B40,"h:mm am/pm") -> 10CX-018-Group-3:20 PM | C14: ='10U_Coed_Champ_36'!L46&"-"&'10U_Coed_Champ_36'!C46&"-"&TEXT('10U_Coed_Champ_36'!B26,"h:mm am/pm") -> 10C-032-Group F-3:20 PM | D14: ='10U_F_Champ-18 teams'!L20&"-"&'10U_F_Champ-18 teams'!C20&"-"&TEXT('10U_F_Champ-18 teams'!B20,"h:mm am/pm") -> 10G-017-RR-3:20 PM | E14: ='10U_Coed_Champ_36'!L26&"-"&'10U_Coed_Champ_36'!C26&"-"&TEXT('10U_Coed_Champ_36'!B26,"h:mm am/pm") -> 10C-031-Group C-3:20 PM | F14: ='10U_Coed_Champ_36'!L66&"-"&'10U_Coed_Champ_36'!C66&"-"&TEXT('10U_Coed_Champ_36'!B46,"h:mm am/pm") -> 10C-033-Group K-3:20 PM | G14: ='10U_F_Champ-18 teams'!L36&"-"&'10U_F_Champ-18 teams'!C36&"-"&TEXT('10U_F_Champ-18 teams'!B36,"h:mm am/pm") -> 10G-018-RR-3:20 PM | I14: ='10U_Coed_Classic 22 from 23'!L22&"-"&'10U_Coed_Classic 22 from 23'!C22&"-"&TEXT('10U_Coed_Classic 22 from 23'!B22,"h:mm am/pm") -> 10CX-021-Group-3:20 PM | J14: 0.63888889 | K14: ='12U_Coed_Champ-45'!L30&"-"&'12U_Coed_Champ-45'!C30&"-"&TEXT('12U_Coed_Champ-45'!B30,"h:mm am/pm") -> 12C-037-Group-3:20 PM | L14: ='12U_Coed_Champ-45'!L48&"-"&'12U_Coed_Champ-45'!C48&"-"&TEXT('12U_Coed_Champ-45'!B48,"h:mm am/pm") -> 12C-044-Group-3:20 PM | M14: ='12U_Coed_Champ-45'!L67&"-"&'12U_Coed_Champ-45'!C67&"-"&TEXT('12U_Coed_Champ-45'!B67,"h:mm am/pm") -> 12C-047-Group-3:20 PM | N14: ='12U_Coed_Champ-45'!L85&"-"&'12U_Coed_Champ-45'!C85&"-"&TEXT('12U_Coed_Champ-45'!B85,"h:mm am/pm") -> 12C-046-Group-3:20 PM | O14: 0.63888889 | P14: ='12U_F_Champ-52'!L39&"-"&'12U_F_Champ-52'!C39&"-"&TEXT('12U_F_Champ-52'!B39,"h:mm am/pm") -> 12G-048-Group-3:20 PM | Q14: ='12U_F_Champ-52'!L78&"-"&'12U_F_Champ-52'!C78&"-"&TEXT('12U_F_Champ-52'!B78,"h:mm am/pm") -> 12G-050-Group-2:30 PM | R14: ='12U_F_Champ-52'!L117&"-"&'12U_F_Champ-52'!C117&"-"&TEXT('12U_F_Champ-52'!B117,"h:mm am/pm") -> 12G-052-Group-3:20 PM | S14: ='12U_F_Champ-52'!L58&"-"&'12U_F_Champ-52'!C58&"-"&TEXT('12U_F_Champ-52'!B58,"h:mm am/pm") -> 12G-049-Group-3:20 PM | T14: ='12U_F_Champ-52'!L98&"-"&'12U_F_Champ-52'!C98&"-"&TEXT('12U_F_Champ-52'!B98,"h:mm am/pm") -> 12G-051-Group-3:20 PM | U14: 0.63888889 | V14: ='14U_F_Champ'!L28&"-"&'14U_F_Champ'!C28&"-"&TEXT('14U_F_Champ'!B28,"h:mm am/pm") -> 14G-041-Group-3:20 PM | W14: ='14U_F_Classic-39 from 40'!L50&"-"&'14U_F_Classic-39 from 40'!C50&"-"&TEXT('14U_F_Classic-39 from 40'!B50,"h:mm am/pm") -> 14GX-044-Group-3:20 PM | X14: ='14U_F_Classic-39 from 40'!L68&"-"&'14U_F_Classic-39 from 40'!C68&"-"&TEXT('14U_F_Classic-39 from 40'!B68,"h:mm am/pm") -> 14GX-038-Group-3:20 PM | Z14: 0.63888889 | AA14: ='14U_F_Classic-39 from 40'!L32&"-"&'14U_F_Classic-39 from 40'!C32&"-"&TEXT('14U_F_Classic-39 from 40'!B32,"h:mm am/pm") -> 14GX-043-Group-3:20 PM | AB14: ='14U_F_Champ'!L47&"-"&'14U_F_Champ'!C47&"-"&TEXT('14U_F_Champ'!B47,"h:mm am/pm") -> 14G-042-Group-3:20 PM | AC14: ='14U_F_Champ'!L66&"-"&'14U_F_Champ'!C66&"-"&TEXT('14U_F_Champ'!B66,"h:mm am/pm") -> 14G-043-Group-3:20 PM | AD14: ='14U_F_Champ'!L85&"-"&'14U_F_Champ'!C85&"-"&TEXT('14U_F_Champ'!B85,"h:mm am/pm") -> 14G-044-Group-3:20 PM | AF14: ='16U_F_Classic-45'!L48&"-"&'16U_F_Classic-45'!C48&"-"&TEXT('16U_F_Classic-45'!B48,"h:mm am/pm") -> 16GX-044-Group-3:20 PM | AG14: ='16U_F_Classic-45'!L30&"-"&'16U_F_Classic-45'!C30&"-"&TEXT('16U_F_Classic-45'!B30,"h:mm am/pm") -> 16GX-037-Group-3:20 PM | AH14: ='16U_F_Classic-45'!L85&"-"&'16U_F_Classic-45'!C85&"-"&TEXT('16U_F_Classic-45'!B85,"h:mm am/pm") -> 16GX-046-Group-3:20 PM | AI14: ='16U_F_Classic-45'!L67&"-"&'16U_F_Classic-45'!C67&"-"&TEXT('16U_F_Classic-45'!B67,"h:mm am/pm") -> 16GX-047-Group-3:20 PM | AJ14: ='16U_F_Champ'!L85&"-"&'16U_F_Champ'!C85&"-"&TEXT('16U_F_Champ'!B85,"h:mm am/pm") -> 16G-044-Group-3:20 PM | AK14: ='18U_F_Classic-44'!L30&"-"&'18U_F_Classic-44'!C30&"-"&TEXT('18U_F_Classic-44'!B30,"h:mm am/pm") -> 18GX-033-Group-3:20 PM | AL14: 0.63888889 | AM14: ='16U_F_Champ'!L28&"-"&'16U_F_Champ'!C28&"-"&TEXT('16U_F_Champ'!B28,"h:mm am/pm") -> 16G-041-Group-3:20 PM | AN14: ='16U_F_Champ'!L47&"-"&'16U_F_Champ'!C47&"-"&TEXT('16U_F_Champ'!B47,"h:mm am/pm") -> 16G-042-Group-3:20 PM | AO14: ='16U_F_Champ'!L66&"-"&'16U_F_Champ'!C66&"-"&TEXT('16U_F_Champ'!B66,"h:mm am/pm") -> 16G-043-Group-3:20 PM | AP14: ='18U_F_Classic-44'!L91&"-"&'18U_F_Classic-44'!C91&"-"&TEXT('18U_F_Classic-44'!B91,"h:mm am/pm") -> 18GX-044-Group-3:20 PM | AQ14: ='18U_F_Classic-44'!L50&"-"&'18U_F_Classic-44'!C50&"-"&TEXT('18U_F_Classic-44'!B50,"h:mm am/pm") -> 18GX-042-Group-3:20 PM | AR14: ='18U_F_Classic-44'!L71&"-"&'18U_F_Classic-44'!C71&"-"&TEXT('18U_F_Classic-44'!B71,"h:mm am/pm") -> 18GX-035-Group-3:20 PM | AU14: 0.70833333 | AX14: ='18U_F_Champ'!L92&"-"&'18U_F_Champ'!C92&"-"&TEXT('18U_F_Champ'!B92,"h:mm am/pm") -> 18G-050-2-3 cross-5:00 PM
